Workbook
Name _: #REF!
Name _: #REF!
Name ____TB112: [2]시산표!#REF!
Name ____TB112: [2]시산표!#REF!
Name ____TB112: #REF!
Name ____TB115: [3]시산표!#REF!
Name ____TB115: [3]시산표!#REF!
Name ____TB115: #REF!
Name ____TB124: [3]시산표!#REF!
Name ____TB124: [3]시산표!#REF!
Name ____TB124: #REF!
Name ____TB125: [3]시산표!#REF!
Name ____TB125: [3]시산표!#REF!
Name ____TB125: #REF!
Name ____TB126: [3]시산표!#REF!
Name ____TB126: [3]시산표!#REF!
Name ____TB126: #REF!
Name ____TB131: [3]시산표!#REF!
Name ____TB131: [3]시산표!#REF!
Name ____TB131: #REF!
Name ____TB132: [3]시산표!#REF!
Name ____TB132: [3]시산표!#REF!
Name ____TB132: #REF!
Name ____TB211: [3]시산표!#REF!
Name ____TB211: [3]시산표!#REF!
Name ____TB211: #REF!
Name ____TB213: [3]시산표!#REF!
Name ____TB213: [3]시산표!#REF!
Name ____TB213: #REF!
Name ____TB214: [3]시산표!#REF!
Name ____TB214: [3]시산표!#REF!
Name ____TB214: #REF!
Name ____TB215: [3]시산표!#REF!
Name ____TB215: [3]시산표!#REF!
Name ____TB215: #REF!
Name ____TB221: [3]시산표!#REF!
Name ____TB221: [3]시산표!#REF!
Name ____TB221: #REF!
Name ____TB2210: [2]시산표!#REF!
Name ____TB2210: [2]시산표!#REF!
Name ____TB2210: #REF!
Name ____TB222: [3]시산표!#REF!
Name ____TB222: [3]시산표!#REF!
Name ____TB222: #REF!
Name ____TB223: [3]시산표!#REF!
Name ____TB223: [3]시산표!#REF!
Name ____TB223: #REF!
Name ____TB224: [3]시산표!#REF!
Name ____TB224: [3]시산표!#REF!
Name ____TB224: #REF!
Name ____TB225: [2]시산표!#REF!
Name ____TB225: [2]시산표!#REF!
Name ____TB225: #REF!
Name ____TB227: [2]시산표!#REF!
Name ____TB227: [2]시산표!#REF!
Name ____TB227: #REF!
Name ____TB229: [2]시산표!#REF!
Name ____TB229: [2]시산표!#REF!
Name ____TB229: #REF!
Name ____TB311: [3]시산표!#REF!

Sheet 5300_기타유동부채
A2: 주식회사 경남제약 | G2: 조서No. 5301
A3: 기타유동부채
A4: LEAD SCHEDULE
A5: 작성자 | C5: 이병하 | E5: 검토자 | G5: 이광우
A6: 작성일 | C6: 46227 | E6: 검토일 | G6: 46227
A7: 결산일 | C7: 46203
E10: 46203 | I10: 비 고
A11: ACCOUNT | B11: 전기잔액 | C11: INCREASE | D11: DECREASE | E11: PER BOOK | F11: AJE | G11: RES | H11: FINAL | I11: Refer | J11: NOTE
A12: 미지급금 | B12: 1534681919 | C12: 14875550933 | D12: 14405417414 | E12: 2004815438 | H12: 2004815438
A13: 미지급비용 | B13: 735115996 | C13: 5935737188 | D13: 6028933721 | E13: 641919463 | H13: 641919463
A14: 선수금 | B14: 1331816 | C14: 11616039249 | D14: 11616039249 | E14: 1331816 | H14: 1331816
A15: 예수금 | B15: 67274989 | C15: 6262044536 | D15: 6270744430 | E15: 58575095 | H15: 58575095
A16: 부가세예수금 | B16: 0 | C16: 5073463073 | D16: 5073463073 | E16: 0 | H16: 0
A17: 임대보증금 | B17: 383000000 | C17: 483000000 | D17: 166000000 | E17: 700000000
A19: 합 계 | B19: 2721404720 | C19: 44245834979 | D19: 43560597887 | E19: 3406641812 | F19: 0 | G19: 0 | H19: 2706641812
A21: ▶ 증감분석
A22: ACCOUNT | B22: 증감금액 | C22: 증감비율 | D22: 비 고
A23: 미지급금 | B23: 470133519 | C23: 0.30633939
A24: 미지급비용 | B24: -93196533 | C24: -0.126778
A25: 일반선수금 | B25: 0 | C25: 0
A26: 예수금 | B26: -8699894 | C26: -0.1293184
A27: 부가세예수금 | B27: 0 | C27: 0
A28: 기타유동부채 | B28: -2146826265 | C28: 0
A31: 회사계정 | B31: 공시계정 | C31: 기초 | D31: 차변 | E31: 대변 | F31: 기말
A32: 미지급금(사원) | B32: 미지급금 | C32: 110911176 | D32: 503640751 | E32: 845109047 | F32: 452379472
A33: 미지급금(거래처) | B33: 미지급금 | C33: 1423770743 | D33: 13901776663 | E33: 14030441886 | F33: 1552435966
A34: 미지급비용(급여) | B34: 미지급비용 | C34: 156477580 | D34: 5341955122 | E34: 5288818422 | F34: 103340880
A35: 미지급비용(이자) | B35: 미지급비용 | C35: 74771526 | D35: 389509609 | E35: 325833973 | F35: 11095890
A36: 미지급비용(신용카드) | B36: 미지급비용 | C36: 53097829 | D36: 297468990 | E36: 321084793 | F36: 76713632
A37: 미지급비용(기타) | B37: 미지급비용 | C37: 450769061 | D37: 0 | E37: 0 | F37: 450769061
A38: 예수금_갑근소득세 | B38: 예수금 | C38: 56138154 | D38: 161095770 | E38: 147020200 | F38: 42062584
A39: 예수금_갑근주민세 | B39: 예수금 | C39: 4885924 | D39: 17041500 | E39: 14708240 | F39: 2552664
A40: 예수금_건강보험 | B40: 예수금 | C40: 0 | D40: 272800060 | E40: 272800060 | F40: 0
A41: 예수금_고용보험 | B41: 예수금 | C41: 1247490 | D41: 49905310 | E41: 49905310 | F41: 1247490
A42: 예수금_국민연금 | B42: 예수금 | C42: 258970 | D42: 249730440 | E42: 249730440 | F42: 258970
A43: 예수금_기타 | B43: 예수금 | C43: 4744451 | D43: 5520171350 | E43: 5527880286 | F43: 12453387
... A47: 일반선수금 | B47: 선수금 | C47: 1331816 | D47: 11616039249 | E47: 11616039249 | F47: 1331816
A50: ▶ 감사절차 (Audit Procedures)
A51: No. | B51: 감사절차 | E51: 경영진 주장 | G51: 수행여부 | H51: 조서번호 | I51: 비 고
A52: 1 | B52: [총괄표 작성 및 전기 대비 검토] 당기말 잔액을 총계정원장과, 전기말 잔액은 전기감사보고서와 대조한다. 양연도간 유의적 변동원인을 파악한다. | E52: E, C, CL | G52: 완료 | H52: 5301
...

Sheet 5300-계정명세_미지급금
A2: 주식회사 경남제약 | G2: 조서No. 5310-1
A3: 기타유동부채
A4: 미지급금명세
C8: 미 지 급 금 명 세 서
C9: 46203
A11: 경남제약㈜ | H11: 단위 : 원
A13: 계정과목 | B13: IFRS | C13: 발생일자 | D13: 거래처코드 | E13: 거래처명 | F13: 적 요 | G13: 금 액 | H13: 비 고
A14: 미지급금(거래처)매입채무및기타채무 | C14: 43830 | D14: R05705 | E14: 더한인관세사무소 | F14: 더한인관세사무소)수입통관비용 선급금(1건) 및 미지급금(2건) 잔액 상계 후 미지급금 계상액(2019년 12월 31일 기준) | G14: 478365
C15: 44104 | D15: R05705 | E15: 더한인관세사무소 | F15: 한인관세사무소)수입통관비용 미수금(5건) 및 미지급금(3건) 잔액 상계 후 미지급금 계상액(2020년 09월 30일 기준) | G15: 756815
C16: 44165 | D16: G01318 | E16: (주)신세계인터내셔날 | F16: 신세계인터네셔널) 2020년 11월 판촉행사장려금_202012-일반유통팀-11 | G16: 386323
C17: 46112 | D17: G02331 | E17: 십일번가 주식회사 | F17: 11번가) 3월 11번가 정산수수료 | G17: 77000 | H17: 7.1일자 상계예정
C18: 46142 | D18: G02485 | E18: 토스 쇼핑 | F18: 비바리퍼블리카) 4월 토스 쇼핑 정산수수료 | G18: 1628
C19: 46143 | D19: R00739 | E19: 넷매니아주식회사 | F19: 넷매니아주식회사) 04월 SendBill 사용요금-아산 / 영업기획팀 | G19: 654720
C20: 46143 | D20: R01914 | E20: (주)데이터코리아 | F20: (주)데이터코리아) 4월 신용조회 비용 / 영업기획팀 | G20: 330000
C21: 46143 | D21: R00739 | E21: 넷매니아주식회사 | F21: 넷매니아주식회사) 04월 Sendbill 사용요금-본사 / 영업관리 | G21: 11550
C22: 46146 | D22: R06679 | E22: 우리정보시스템/잉크몬스터 대구중앙지사 | F22: 우리정보시스템)복합기 임대료/의령공장 품질관리/202410-품질관리팀_의령-58 | G22: 154000
C23: 46146 | D23: Z00924 | E23: (주)샘타코biokorea | F23: 샘타코)동물실험용(자하거추출물(7226002), 아산공장 플라젠시아주(26003,26004))마우스 구입/의령공장 품질관리 | G23: 296800
C24: 46146 | D24: R05479 | E24: 주식회사엠비바이오 | F24: 주식회사 엠비바이오) 미생물시험 배지 구매/202605-제품파트-7 | G24: 2511300
C25: 46148 | D25: Z01006 | E25: 주식회사 웨이투웨이 | F25: 품질보증팀 온습도계 센서 검교정 실시의 건/202604-운영파트_품질-15 | G25: 145200
C26: 46150 | D26: R06110 | E26: (주)아주과학 | F26: 아주과학)아미노산 분석 소모품 구매/의령공장 품질관리 | G26: 11357500
C27: 46153 | D27: R05021 | E27: 한국유량계공업(주) | F27: 한국유량계공업) 터빈 유량계 검교정 비용/의령공장 생산파트 | G27: 220000
C28: 46153 | D28: R05134 | E28: 탑마킹시스템 | F28: 탑마킹시스템)생산소모품(필로우포장기 인쇄용 리본)구입비/202605-포장파트-11 | G28: 594000
C29: 46153 | D29: R06548 | E29: 제이에스 BIO | F29: 제이에스 BIO)동물실험용(자하거추출물(7226002), 대한뉴팜 자하거추출물(7226001)) 고양이 구입/의령공장 품질관리 | G29: 650000
... C109: 46177 | D109: R05572 | E109: 진성로지스틱스3101 | F109: 아산→용인 용달화물차 운임비(6/4) / 아산공장 물류파트 | G109: 132000
C110: 46178 | D110: R03801 | E110: 웅진코웨이㈜ | F110: 웅진코웨이) 26년 5월 본사 비데10대 렌탈비 / 202406-인사팀-63, 202506-인사팀-53 | G110: 23270 | H110: 5월 렌탈비 반제 잔액분
C111: 46178 | D111: R06875 | E111: 주식회사 아산자재 | F111: 아산자재)배관 보수 자재 및 공무용품 구매의 건/ 202605-공무파트-49 / 아산공장 공무파트 | G111: 162800
C112: 46178 | D112: R05749 | E112: 주식회사 바이오푸드랩 | F112: 품질보증팀 아산공장 식품 자가품질위탁시험 분석 의뢰의 건/202606-관리파트_품질-10 | G112: 88000
C113: 46178 | D113: R06156 | E113: (주)인에이지 | F113: (주)인에이지)2026년 6월분 그룹웨어 유지보수료 / 202008-IT-12, 202112-IT-9 | G113: 495000
C114: 46178 | D114: R01776 | E114: 호스트웨이아이디씨(주) | F114: 호스트웨이아이디씨㈜)2026년 6월 HOSTWAY IDC 사용료 /전산팀 | G114: 1716000
C115: 46178 | D115: R07413 | E115: 싸이언츠테크놀로지 | F115: [아산공장 품질관리팀]용출시험기(CL-050, CL-051) 수리건/202606-제품파트-29 | G115: 1606000
C116: 46181 | D116: R06873 | E116: 염치용달 | F116: 아산→용인 용달화물차 운임비(6/8) / 아산공장 물류파트 | G116: 132000
C117: 46181 | D117: H00236 | E117: 국제씨엘에스(주) | F117: 국제씨엘에스)TOC장비 소모품 구입/의령공장 품질관리 | G117: 1078000
C118: 46181 | D118: R06946 | E118: 주식회사글로벌소프트 | F118: (주)글로벌소프트)MS365, 한글2024 구매 건 / 202606-IT-2 | G118: 557920
C119: 46182 | D119: R06796 | E119: 동행로지스 | F119: 아산→용인 용달화물차 운임비(6/9) / 아산공장 물류파트 | G119: 242000
C120: 46183 | D120: R06823 | E120: 주식회사 아이티센코어(구.굿센) | F120: 6월 내부회계관리시스템 클라우드 서비스 사용료/202207-IT-4 | G120: 770000
C121: 46183 | D121: R04458 | E121: (주)와이젠정보기술 | F121: ㈜와이젠정보기술)2026년 6월 서버 유지보수료 /전산팀 /202007-IT-11 | G121: 1870000
C122: 46183 | D122: R03823 | E122: (주)지엠피아이티 | F122: ㈜지엠피아이티)2026년 6월분 ERP 유지보수료 /전산팀/202209-IT-9 | G122: 3300000
... C478: 46203 | D478: R05946 | E478: 롯데쇼핑(주)롯데슈퍼사업본부 | F478: 롯데슈퍼) 06월 성장장려금 | G478: 385544
C479: 46203 | D479: R05203 | E479: (주)비지에프리테일 | F479: 비지에프리테일) 6월 신상품장려금(대금공제)
C480: 46203 | D480: R07491 | E480: 대한상사 | F480: 대한상사) 6월 농협 위탁 벤더수수료 | G480: 1065538
...

Sheet 5300-계정명세_미지급금(사원)상세
A2: 주식회사 경남제약 | G2: 조서No. 5310-2
A3: 기타유동부채
A4: 미지급금(사원)명세
E8: =SUM(E10:E203) -> 452379472
A9: 발생일자 | B9: 거래처코드 | C9: 거래처명 | D9: 적 요 | E9: 금 액
A10: 44470 | B10: a20001 | C10: 배건우 | D10: 前 배건우 대표 퇴직금(20.03.25~21.09.23), 202112-인사팀-44 | E10: 40726790 | J10: 이름 | K10: 부서 | L10: 사원번호
A11: 46182 | B11: =VLOOKUP(C11,$J:$L,3,0) -> 223026 | C11: 장윤지 | D11: 225028 의약사업본부) 최봉준이사 5월 이동전화료(통신비) | E11: 70000 | J11: 조정영 | K11: 대표이사 | L11: a22009
A12: 46197 | B12: =VLOOKUP(C12,$J:$L,3,0) -> 223040 | C12: 신보근 | D12: 225028 아산공장 미팅 유류비(202606-개발팀-80) | E12: 55476 | J12: 임도형 | K12: 사장실 | L12: a22011
A13: 46197 | B13: =VLOOKUP(C13,$J:$L,3,0) -> 223040 | C13: 신보근 | D13: 225028 아산공장 미팅 톨비(202606-개발팀-80) | E13: 16300 | J13: 최윤범 | K13: 온라인사업본부 | L13: a22022
A14: 46199 | B14: =VLOOKUP(C14,$J:$L,3,0) -> 225027 | C14: 한가영 | D14: 225028 개인경비 사용 정산 신청의 건(백찬) / 202607-물류파트-4 | E14: 175000 | J14: 최제영 | K14: 영업관리팀 | L14: 220034
A15: 46202 | B15: =VLOOKUP(C15,$J:$L,3,0) -> 220048 | C15: 홍경민 | D15: 225028 제제연구팀 홍경민대리_2026 06월 개인경비 사용 정산_202606-제제연구팀-11 | E15: 46100 | J15: 최제영a | K15: 영업관리팀 | L15: 220034
A16: 46202 | B16: =VLOOKUP(C16,$J:$L,3,0) -> 210082 | C16: 조승평 | D16: 225028 감사팀)06.29 6월 시내외 교통비 정산건/202607-감사팀-4 | E16: 29450 | J16: 박현우 | K16: 일반유통팀 | L16: 223011
A17: 46203 | B17: =VLOOKUP(C17,$J:$L,3,0) -> 225001 | C17: 고요한 | D17: 225028 CS파트) 2606-01 클레임 교환품 택배발송_202606-CS파트-12 (6/2)_202606-CS파트-42 | E17: 4500 | J17: 여성재 | K17: 일반유통팀 | L17: 224004
A18: 46203 | B18: =VLOOKUP(C18,$J:$L,3,0) -> 225001 | C18: 고요한 | D18: 225028 CS파트) 클레임 교환품 택배 발송용 소모품 구입 (6/2)_202606-CS파트-42 | E18: 10000 | J18: 강승한 | K18: 특수유통팀 | L18: 223024
A19: 46203 | B19: =VLOOKUP(C19,$J:$L,3,0) -> 225001 | C19: 고요한 | D19: 225028 CS파트) 회의비 사용 (6/8)_202606-CS파트-42 | E19: 23000 | J19: 이주운 | K19: 특수유통팀 | L19: 224072
A20: 46203 | B20: =VLOOKUP(C20,$J:$L,3,0) -> 225001 | C20: 고요한 | D20: 225028 CS파트) 클레임 교환품 택배 발송용 소모품 구입 (6/8)_202606-CS파트-42 | E20: 13800 | J20: 이선영 | K20: 상품기획마케팅팀 | L20: 222060
A21: 46203 | B21: =VLOOKUP(C21,$J:$L,3,0) -> 225001 | C21: 고요한 | D21: 225028 CS파트) 회의비 사용 (6/18)_202606-CS파트-42 | E21: 26000 | J21: 이상근 | K21: 상품기획마케팅팀 | L21: 223009
A22: 46203 | B22: =VLOOKUP(C22,$J:$L,3,0) -> 225001 | C22: 고요한 | D22: 225028 CS파트) 2606-18,19 클레임 교환품 택배발송_202606-CS파트-29,30 (6/19)_202606-CS파트-42 | E22: 9000 | J22: 김규희 | K22: 상품기획마케팅팀 | L22: 222067
A23: 46203 | B23: =VLOOKUP(C23,$J:$L,3,0) -> 225001 | C23: 고요한 | D23: 225028 CS파트) 회의비 사용 (6/23)_202606-CS파트-42 | E23: 33000 | J23: 임지혜 | K23: 상품기획마케팅팀 | L23: 219013
A24: 46203 | B24: =VLOOKUP(C24,$J:$L,3,0) -> 225001 | C24: 고요한 | D24: 225028 CS파트) 2606-21,22 클레임 교환품 택배발송_202606-CS파트-32,33 (6/24)_202606-CS파트-42 | E24: 12000 | J24: 장하경 | K24: 영업관리팀 | L24: 220040
A25: 46203 | B25: =VLOOKUP(C25,$J:$L,3,0) -> 225001 | C25: 고요한 | D25: 225028 CS파트) 2606-29 클레임 교환품 택배발송_202606-CS파트-40 (6/29)_202606-CS파트-42 | E25: 4500 | J25: 이성우 | K25: 의약사업마케팅본부 | L25: a22020
A26: 46203 | B26: =VLOOKUP(C26,$J:$L,3,0) -> 223025 | C26: 이하늘 | D26: 225028 (마케팅팀) 개인경비 청구의 건 / 202606-마케팅팀-88 | E26: 14200 | J26: 신보근 | K26: 의약품개발팀 | L26: 223040
A27: 46203 | B27: =VLOOKUP(C27,$J:$L,3,0) -> 223025 | C27: 이하늘 | D27: 225028 (마케팅팀) 개인경비 청구의 건 / 202606-마케팅팀-88 | E27: 19900 | J27: 임종범 | K27: 의약품개발팀 | L27: 223048
A28: 46203 | B28: =VLOOKUP(C28,$J:$L,3,0) -> 223025 | C28: 이하늘 | D28: 225028 마케팅개발본부) 이성우 이사 6월 고지분 통신비(5월 이용분) | E28: 70000 | J28: 조규민 | K28: 의약사업마케팅팀 | L28: 218005
A29: 46203 | B29: =VLOOKUP(C29,$J:$L,3,0) -> 222012 | C29: 유재용 | D29: 225028 유재용 선임) 06월 개인경비/202606-생산파트-26/202606-생산파트-29 | E29: 19650 | J29: 고재민 | K29: 의약사업마케팅팀 | L29: 223002
A30: 46203 | B30: =VLOOKUP(C30,$J:$L,3,0) -> 222067 | C30: 김규희 | D30: 225028 06/04 퀵 발송 비용 (산리오 키링 샘플 감수 1차) | E30: 14900 | J30: 박우진 | K30: 의약사업마케팅팀 | L30: 221015
A31: 46203 | B31: =VLOOKUP(C31,$J:$L,3,0) -> 222067 | C31: 김규희 | D31: 225028 06/08 퀵 발송 비용 (산리오 키링 샘플 감수 2차) | E31: 9600 | J31: 윤지현 | K31: 의약사업마케팅팀 | L31: 224057
A32: 46203 | B32: =VLOOKUP(C32,$J:$L,3,0) -> 222067 | C32: 김규희 | D32: 225028 06/15 산리오 키링 샘플 발송/디자인룩 계약서 발송 우편비 | E32: 8080 | J32: 정다정 | K32: 구매파트 | L32: 219050
A33: 46203 | B33: =VLOOKUP(C33,$J:$L,3,0) -> 222067 | C33: 김규희 | D33: 225028 06/24 퀵 발송 비용 (산리오 키링 샘플 감수 3차) | E33: 8600 | J33: 정조운 | K33: 구매파트 | L33: 223041
A34: 46203 | B34: =VLOOKUP(C34,$J:$L,3,0) -> 222067 | C34: 김규희 | D34: 225028 06/29 칼로 컷앤리셋 외근 교통비 (외근지 평택) | E34: 4300 | J34: 이정민 | K34: 디자인파트 | L34: 223023
A35: 46203 | B35: =VLOOKUP(C35,$J:$L,3,0) -> a22021 | C35: 양재성 | D35: 225028 도매팀_양재성 통행료정산(06/08~06.17) | E35: 37740 | J35: 김정예 | K35: 디자인파트 | L35: 224031
A36: 46203 | B36: =VLOOKUP(C36,$J:$L,3,0) -> a22021 | C36: 양재성 | D36: 225028 도매팀)양재성_통신비_이동전화료 | E36: 70000 | J36: 고요한 | K36: CS파트 | L36: 225001
A37: 46203 | B37: =VLOOKUP(C37,$J:$L,3,0) -> 218005 | C37: 조규민 | D37: 225028 [마케팅팀] 26년 6월 개인경비 사용 정산 신청의 건 / 202606-마케팅팀-100 | E37: 25400 | J37: 박상준 | K37: 지원본부 | L37: a22010
A38: 46203 | B38: =VLOOKUP(C38,$J:$L,3,0) -> 223002 | C38: 고재민 | D38: 225028 [마케팅팀] 26년 6월 개인경비 사용 정산 신청의 건_고재민 / 202606-마케팅팀-99 | E38: 199605 | J38: 조승평 | K38: 감사팀 | L38: 210082
A39: 46203 | B39: =VLOOKUP(C39,$J:$L,3,0) -> 224051 | C39: 한승희 | D39: 225028 2026년 6월 개인경비 사용 정산/202607-감사팀-5 | E39: 32850 | J39: 한승희 | K39: 감사팀 | L39: 224051
A40: 46203 | B40: =VLOOKUP(C40,$J:$L,3,0) -> 220052 | C40: 배지혜 | D40: 225028 위탁업체 (주)한국파비스제약 현장 Audit 출장 통행료/202606-운영파트_품질-7 | E40: 7500 | J40: 이종석 | K40: 감사팀 | L40: 222053
A41: 46203 | B41: =VLOOKUP(C41,$J:$L,3,0) -> 220052 | C41: 배지혜 | D41: 225028 위탁업체 (주)한국파비스제약 현장 Audit 출장 주유비/202606-운영파트_품질-7 | E41: 32562 | J41: 박성인 | K41: 인사팀 | L41: 223045
A42: 46203 | B42: =VLOOKUP(C42,$J:$L,3,0) -> 220052 | C42: 배지혜 | D42: 225028 위탁업체 (주)한국파비스제약 현장 Audit 출장 통행료/202606-운영파트_품질-7 | E42: 7000 | J42: 김우진 | K42: 인사팀 | L42: 220029
A43: 46203 | B43: =VLOOKUP(C43,$J:$L,3,0) -> 220052 | C43: 배지혜 | D43: 225028 위탁업체 (주)한국파비스제약 현장 Audit 출장 주유비/202606-운영파트_품질-7 | E43: 32562 | J43: 전계준 | K43: 인사팀 | L43: 223035
A44: 46203 | B44: =VLOOKUP(C44,$J:$L,3,0) -> 220052 | C44: 배지혜 | D44: 225028 위탁업체 (주)한국파비스제약 현장 Audit 출장 식비/202606-운영파트_품질-7 | E44: 24000 | J44: 이시현 | K44: 인사팀 | L44: 223058
...

Sheet 5300_계정명세_예수금
A2: 주식회사 경남제약 | G2: 조서No. 5310-3
A3: 기타유동부채
A4: 예수금명세
A8: 예 수 금 명 세 서
A9: 46203
A10: 경남제약㈜ | G10: 단위 : 원
A11: 계정과목 | B11: IFRS | C11: 거래처 | D11: 발생일 | E11: 내 역 | F11: 금 액 | G11: 비 고
A12: 갑근소득세 | B12: 기타유동부채 | C12: 경남제약㈜ | F12: 42062584
A13: 갑근주민세 | C13: 경남제약㈜ | F13: 2552664
A14: 국민연금 | C14: 경남제약㈜ | F14: 258970
A15: 고용보험 | C15: 경남제약㈜ | F15: 1247490
A16: 건강보험 | C16: 경남제약㈜
A17: 기타 | C17: 경남제약㈜ | F17: 12453387
A18: 부가세 | C18: 경남제약㈜ | E18: 부가세 예대 대체 후 잔액
A19: 합 계 | F19: =F14+F15+F17+F13+F12 -> 58575095
F21: =F19='5300_기타유동부채'!E15 -> TRUE

Sheet 5300_계정명세_일반선수금
A2: 주식회사 경남제약 | G2: 조서No. 5310-4
A3: 기타유동부채
A4: 선수금명세
A8: 선 수 금 명 세 서 | J8: 기타유동부채
B9: 46203
B10: 경남제약㈜ | I10: 단위 : 원
B12: 계정과목 | C12: IFRS | D12: 발생일자 | E12: 코드 | F12: 거래처명 | G12: 적 요 | H12: 금 액 | I12: 비 고
D13: 44896 | E13: R035506 | F13: 선수금 기타 거래처 | G13: 유오동 선수금 입금 | H13: 200000
D14: 45442 | E14: R035506 | F14: 선수금 기타 거래처 | G14: 미확인 입금건 선수금처리(입금자명 : 오선진) | H14: 1131816
D15: 46100 | E15: R035506 | F15: 선수금 기타 거래처 | G15: 전환사채 5회차 매각 계약금
D16: 46100 | E16: R035506 | F16: 선수금 기타 거래처 | G16: 전환사채 6회차 매각 계약금
B17: 합 계 | H17: =SUM(H13:H16) -> 1331816
H19: =H17='5300_기타유동부채'!H14 -> TRUE
B25: *수금 등록 현황 - 승인중 (상태 : 미완료)
B26: 보조부원장
B27: 관리항목원장

Sheet 5300-계정명세_미지급비용
A2: 주식회사 경남제약 | G2: 조서No. 5310-5
A3: 기타유동부채
A4: 미지급비용명세
B8: 미 지 급 비 용 명 세 서 | K8: 매입채무및기타채무
B9: 46203
B10: 경남제약(주) | I10: 단위: 원
B12: 계정과목 | C12: IFRS | D12: 관리항목값 | E12: 관리항목명 | F12: 전표일자 | G12: 적 요 | H12: 금액 | I12: 비고
B13: 미지급비용(급여) | F13: 44469 | G13: 서울 및 지점) 9월 급여 | H13: 15101904 | J13: 前 배건우대표
F14: 2021-10-01 | G14: 前 배건우대표 사임에 따른 미지급 급여(9월) | H14: 8655976 | J14: 前 배건우대표 수정신고분
F15: 46203 | G15: 영업기획팀) 2026년 6월 의약사업본부 소매 인센티브/202607-영업기획팀-16 | H15: 2100000
F16: 46203 | G16: 의약사업본부)2026년 상반기 인센티브/202607-영업기획팀-16 | H16: =5200000 -> 5200000
F17: 46203 | G17: 의약사업본부)2026년 2분기 인센티브/202607-영업기획팀-16 | H17: 49948000
F18: 46203 | G18: [마케팅팀] 2026년 6월 자해생력 담당자 지원 정책 정산의 건/ 202607-마케팅팀-52 | H18: 22335000
B19: 소계 | H19: =SUM(H13:H18) -> 103340880
B21: 미지급비용(신용카드) | C21: 매입채무및기타채무 | F21: 46203 | G21: 2026년 6월 법인카드 사용 | H21: 76713632
B22: 소계 | H22: =SUM(H21) -> 76713632
B24: 미지급비용(기타) | D24: A10446 | E24: 경남제약주식회사 | F24: 46022 | G24: 2025_4Q 미사용연차수당 부채계상 | H24: 450769061
B25: 소계 | H25: =SUM(H24:H24) -> 450769061
B27: 미지급비용(이자) | E27: 신한은행 | F27: 46112 | G27: 2026.6M 미지급이자(6.13~6.30) 계상(신한50억*4.5%*18/365) | H27: 11095890
B28: 소계 | H28: =SUM(H27:H27) -> 11095890
B29: 합계 | H29: =H19+H22+H25+H28 -> 641919463
H32: =H29='5300_기타유동부채'!H13 -> TRUE

Sheet 5300_기타유동부채_총계정원장
A2: 주식회사 경남제약 | G2: 조서No. 5320
A3: 기타유동부채
A4: 월별증감
A7: 미지급금_거래처
A8: 월 | B8: 차변합계 | C8: 차변건수 | D8: 대변합계 | E8: 대변건수 | G8: *1 | H8: 미지급금(거래처) 4월 증가 원인은 인콘 골프회원권 양수2,981,000천원으로 인한 영향
A9: 2026-01 | B9: 1605899052 | C9: 584 | D9: 1384975959 | E9: 607
A10: 2026-02 | B10: 1227615881 | C10: 536 | D10: 1464676011 | E10: 539
A11: 2026-03 | B11: 2128466455 | C11: 665 | D11: 2235740528 | E11: 588
A12: 2026-04 | B12: 4707973269 | C12: 608 | D12: 5262772548 | E12: 593 | F12: *1
A13: 2026-05 | B13: 2091600555 | C13: 515 | D13: 1415896443 | E13: 612
A14: 2026-06 | B14: 2140221451 | C14: 745 | D14: 2266380397 | E14: 701
A15: 2026-07 | B15: 0 | C15: 0 | D15: 0 | E15: 0
A16: 2026-08 | B16: 0 | C16: 0 | D16: 0 | E16: 0
A17: 2026-09 | B17: 0 | C17: 0 | D17: 0 | E17: 0
A18: 2026-10 | B18: 0 | C18: 0 | D18: 0 | E18: 0
A19: 2026-11 | B19: 0 | C19: 0 | D19: 0 | E19: 0
A20: 2026-12 | B20: 0 | C20: 0 | D20: 0 | E20: 0
A21: 합 계 | B21: 13901776663 | C21: 3653 | D21: 14030441886 | E21: 3640
A23: 미지급금_사원
A24: 월 | B24: 차변합계 | C24: 차변건수 | D24: 대변합계 | E24: 대변건수
A25: 2026-01 | B25: 73205656 | C25: 193 | D25: 56443564 | E25: 166
A26: 2026-02 | B26: 55491364 | C26: 163 | D26: 196571129 | E26: 161
A27: 2026-03 | B27: 200728419 | C27: 169 | D27: 73754290 | E27: 187
A28: 2026-04 | B28: 71463870 | C28: 183 | D28: 60365236 | E28: 218
A29: 2026-05 | B29: 58677756 | C29: 216 | D29: 44023686 | E29: 194
A30: 2026-06 | B30: 44073686 | C30: 193 | D30: 413951142 | E30: 198
A31: 2026-07 | B31: 0 | C31: 0 | D31: 0 | E31: 0
A32: 2026-08 | B32: 0 | C32: 0 | D32: 0 | E32: 0
A33: 2026-09 | B33: 0 | C33: 0 | D33: 0 | E33: 0
A34: 2026-10 | B34: 0 | C34: 0 | D34: 0 | E34: 0
A35: 2026-11 | B35: 0 | C35: 0 | D35: 0 | E35: 0
A36: 2026-12 | B36: 0 | C36: 0 | D36: 0 | E36: 0
A37: 합 계 | B37: 503640751 | C37: 1117 | D37: 845109047 | E37: 1124
A39: 미지급비용_급여
A40: 월 | B40: 차변합계 | C40: 차변건수 | D40: 대변합계 | E40: 대변건수
A41: 2026-01 | B41: 957374482 | C41: 4 | D41: 877129962 | E41: 8
A42: 2026-02 | B42: 1022971913 | C42: 4 | D42: 992958973 | E42: 8
A43: 2026-03 | B43: 811432975 | C43: 3 | D43: 849100715 | E43: 8
A44: 2026-04 | B44: 839658132 | C44: 3 | D44: 814981332 | E44: 6
A45: 2026-05 | B45: 846167645 | C45: 3 | D45: 826832645 | E45: 6
...

Sheet 5300_주석
A2: 주식회사 경남제약 | G2: 조서No. 5330
A3: 기타유동부채
A4: 주석
A7: 당반기말과 전기말 현재 매입채무및기타채무의 내역은 다음과 같습니다.
A8: (단위: 원)
A9: 구 분 | B9: 당반기말 | E9: 전기말
B10: 유 동 | C10: 비유동 | D10: 합 계 | E10: 유 동 | F10: 비유동 | G10: 합 계
A11: 미지급금 | B11: ='5300_기타유동부채'!H12 -> 2004815438 | C11: 0 | D11: =SUM(B11:C11) -> 2004815438 | E11: ='5300_기타유동부채'!B12 -> 1534681919 | F11: 0 | G11: =SUM(E11:F11) -> 1534681919
A12: 미지급비용 | B12: ='5300_기타유동부채'!H13 -> 641919463 | C12: 0 | D12: =SUM(B12:C12) -> 641919463 | E12: ='5300_기타유동부채'!B13 -> 735115996 | F12: 0 | G12: =SUM(E12:F12) -> 735115996
A15: 당반기말과 전기말 현재 기타부채의 내역은 다음과 같습니다.
A16: (단위: 원)
A17: 구 분 | B17: 당반기말 | E17: 전기말
B18: 유동 | C18: 비유동 | D18: 합계 | E18: 유동 | F18: 비유동 | G18: 합계
A19: 선수금 | B19: ='5300_기타유동부채'!H14 -> 1331816 | D19: =SUM(B19:C19) -> 1331816 | E19: ='5300_기타유동부채'!B14 -> 1331816 | G19: =SUM(E19:F19) -> 1331816
A20: 예수금 | B20: ='5300_기타유동부채'!H15 -> 58575095 | D20: =SUM(B20:C20) -> 58575095 | E20: ='5300_기타유동부채'!B15 -> 67274989 | G20: =SUM(E20:F20) -> 67274989
