Workbook

Sheet 기본사항
A2: 감사조서 기본사항
A3: Basic Information of Working Papers
A5: ※ 아래 항목을 입력하면 모든 감사조서에 자동으로 반영됩니다.
B7: 항 목 | C7: 입력값 | D7: 비 고
B8: 회사명 | C8: 주식회사 XXX | D8: 피감사회사의 정확한 법인명을 입력하세요
B9: 감사기간 시작일 | C9: 2025-01-01 | D9: 예: 2025-01-01
B10: 감사기간 종료일 | C10: 2025-12-31 | D10: 예: 2025-12-31 ← 각 시트 결산일에 자동 반영
A13: ▶ 셀 참조 정보 (각 시트에서 아래 셀을 참조합니다)
B14: 기본사항!C8 | C14: → 회사명
B15: 기본사항!C9 | C15: → 감사기간 시작일
B16: 기본사항!C10 | C16: → 감사기간 종료일 (결산일 / 당기 헤더에 자동 반영)

Sheet 목차
A2: =기본사항!C8 -> 주식회사 XXX
A3: 감사조서 목차 (Index of Working Papers)
A4: 결산일: 2025년 12월 31일
B6: 조서번호 | C6: 계정과목 | D6: 담당자 | E6: 비고
B7: 4201 | C7: =HYPERLINK("#현예금!A1","현금및현금성자산") -> 현금및현금성자산
B8: 4301 | C8: =HYPERLINK("#매출채권!A1","매출채권") -> 매출채권
B9: 4401 | C9: =HYPERLINK("#재고자산!A1","재고자산") -> 재고자산
B10: 4501 | C10: =HYPERLINK("#유형자산!A1","유형자산") -> 유형자산
B11: 4601 | C11: =HYPERLINK("#장단기차입금!A1","장단기차입금") -> 장단기차입금
B12: 4701 | C12: =HYPERLINK("#매출!A1","매출") -> 매출
B13: 4801 | C13: =HYPERLINK("#판관비!A1","판매비및관리비") -> 판매비및관리비
A16: ※ 색상 범례: 파란 글씨 = 수식/링크 │ 보라 글씨 = 감사분석 체크항목 │ 노란 배경 = 분석 포인트 섹션

Sheet 장단기차입금
A2: =기본사항!C8 -> 주식회사 XXX | G2: 조서No. 4601
A3: 장단기차입금
A4: LEAD SCHEDULE
A5: 작성자 | E5: 검토자
A6: 작성일 | E6: 검토일
A7: 결산일 | C7: =기본사항!C10 -> 2025-12-31
B10: 전 기 | E10: =기본사항!C10 -> 2025-12-31 | I10: 비 고
A11: ACCOUNT | B11: 전기잔액 | C11: INCREASE | D11: DECREASE | E11: PER BOOK | F11: AJE | G11: RES | H11: FINAL | I11: Refer | J11: NOTE
A12: 단기차입금 | I12: 4610
A13: 유동성장기부채 | I13: 4620
A14: 장기차입금 | I14: 4630
A15: 사채 | I15: 4640
A17: 합 계 | B17: =SUM(B12:B15) -> 0 | C17: =SUM(C12:C15) -> 0 | D17: =SUM(D12:D15) -> 0 | E17: =SUM(E12:E15) -> 0 | F17: =SUM(F12:F15) -> 0 | G17: =SUM(G12:G15) -> 0 | H17: =SUM(H12:H15) -> 0
A19: ▶ 증감분석
A20: ACCOUNT | B20: 증감금액 | C20: 증감비율 | D20: 비 고
A21: 단기차입금
A22: 유동성장기부채
A23: 장기차입금
A24: 사채
A27: ▶ 감사분석 포인트 (Audit Analysis Points)
A28: ☐ 잔액확인서 징구 | C28: 주요 금융기관으로부터 차입금 잔액확인서 징구 및 원장 대사
A29: ☐ 유동·비유동 분류 | C29: 만기일 기준 유동성 분류 적정성, 만기연장 약정 존재 여부 확인
A30: ☐ 이자비용 검증 | C30: 이자율 × 차입금 평잔으로 이자비용 추정 후 계상액과 비교
A31: ☐ 담보·보증 현황 | C31: 차입금 관련 담보제공 자산 및 지급보증 현황 파악, 주석 공시 충분성
A32: ☐ 특약사항(Covenant) 검토 | C32: 재무비율 유지의무 등 차입약정 위반 여부 및 기한이익상실 가능성
A33: ☐ 특수관계자 차입 | C33: 특수관계자 차입금 금리 및 조건 적정성, 시장이자율과 비교
A35: ※ 본 감사조서는 「주식회사 등의 외부감사에 관한 법률」에 따라 작성되었습니다.

Sheet 매출
A2: =기본사항!C8 -> 주식회사 XXX | G2: 조서No. 4701
A3: 매출
A4: LEAD SCHEDULE
A5: 작성자 | E5: 검토자
A6: 작성일 | E6: 검토일
A7: 결산일 | C7: =기본사항!C10 -> 2025-12-31
B10: 전 기 | E10: =기본사항!C10 -> 2025-12-31 | I10: 비 고
A11: ACCOUNT | B11: 전기잔액 | C11: INCREASE | D11: DECREASE | E11: PER BOOK | F11: AJE | G11: RES | H11: FINAL | I11: Refer | J11: NOTE
A12: 상품매출 | I12: 4710
A13: 제품매출 | I13: 4720
A14: 용역매출 | I14: 4730
A15: 임대료수입 | I15: 4740
A17: 합 계 | B17: =SUM(B12:B15) -> 0 | C17: =SUM(C12:C15) -> 0 | D17: =SUM(D12:D15) -> 0 | E17: =SUM(E12:E15) -> 0 | F17: =SUM(F12:F15) -> 0 | G17: =SUM(G12:G15) -> 0 | H17: =SUM(H12:H15) -> 0
A19: ▶ 증감분석
A20: ACCOUNT | B20: 증감금액 | C20: 증감비율 | D20: 비 고
A21: 상품매출
A22: 제품매출
A23: 용역매출
A24: 임대료수입
A27: ▶ 감사분석 포인트 (Audit Analysis Points)
A28: ☐ 수익인식 시점 검토 | C28: 수행의무 이행 시점(인도기준/진행기준) 적정성, K-IFRS 1115 준수 여부
A29: ☐ Cut-off 검토 | C29: 결산일 전후 매출의 기간 귀속 적정성, 선수수익 계상 여부
A30: ☐ 월별 추이 분석 | C30: 월별 매출 추이 분석, 계절성과 맞지 않는 급증·급감 원인 파악
A31: ☐ 반품·에누리 처리 | C31: 반품·할인·에누리의 매출 차감 또는 충당부채 계상 적정성
A32: ☐ 특수관계자 매출 | C32: 특수관계자 매출 금액·가격 적정성 및 독립거래 조건 비교
A33: ☐ 세금계산서 대사 | C33: 매출 원장과 세금계산서 합계 대사, 누락·이중 발행 여부
A35: ※ 본 감사조서는 「주식회사 등의 외부감사에 관한 법률」에 따라 작성되었습니다.

Sheet 판관비
A2: =기본사항!C8 -> 주식회사 XXX | G2: 조서No. 4801
A3: 판매비및관리비
A4: LEAD SCHEDULE
A5: 작성자 | E5: 검토자
A6: 작성일 | E6: 검토일
A7: 결산일 | C7: =기본사항!C10 -> 2025-12-31
B10: 전 기 | E10: =기본사항!C10 -> 2025-12-31 | I10: 비 고
A11: ACCOUNT | B11: 전기잔액 | C11: INCREASE | D11: DECREASE | E11: PER BOOK | F11: AJE | G11: RES | H11: FINAL | I11: Refer | J11: NOTE
A12: 급여 | I12: 4810
A13: 퇴직급여 | I13: 4820
A14: 복리후생비 | I14: 4830
A15: 감가상각비 | I15: 4840
A16: 지급임차료 | I16: 4850
A17: 지급수수료 | I17: 4860
A18: 광고선전비 | I18: 4870
A19: 기타판관비 | I19: 4890
A21: 합 계 | B21: =SUM(B12:B19) -> 0 | C21: =SUM(C12:C19) -> 0 | D21: =SUM(D12:D19) -> 0 | E21: =SUM(E12:E19) -> 0 | F21: =SUM(F12:F19) -> 0 | G21: =SUM(G12:G19) -> 0 | H21: =SUM(H12:H19) -> 0
A23: ▶ 증감분석
A24: ACCOUNT | B24: 증감금액 | C24: 증감비율 | D24: 비 고
A25: 급여
A26: 퇴직급여
A27: 복리후생비
A28: 감가상각비
A29: 지급임차료
A30: 지급수수료
A31: 광고선전비
A32: 기타판관비
A35: ▶ 감사분석 포인트 (Audit Analysis Points)
A36: ☐ 전기 대비 분석적 검토 | C36: 주요 비목별 금액 및 비율 전기 비교, 유의적 변동 원인 파악
A37: ☐ 급여 검증 | C37: 급여대장 vs 원천징수이행상황신고서 대사, 임원보수한도 초과 여부
A38: ☐ 퇴직급여 검증 | C38: 퇴직급여충당부채 설정액 적정성, 확정급여형/확정기여형 구분
A39: ☐ 자본적 지출 혼입 여부 | C39: 비용 처리된 항목 중 자산화 대상 지출 포함 여부 검토
A40: ☐ 접대비 한도 초과 | C40: 접대비 세법 한도 초과 여부 및 증빙 구비 현황
A41: ☐ 선급비용 계상 | C41: 기간 미도래 비용의 선급비용 처리 여부(보험료·임차료 등)
A43: ※ 본 감사조서는 「주식회사 등의 외부감사에 관한 법률」에 따라 작성되었습니다.

Sheet 현예금
A2: =기본사항!C8 -> 주식회사 XXX | G2: 조서No. 4101
A3: 현금및현금성자산 · 장단기금융상품
A4: LEAD SCHEDULE
A5: 작성자 | E5: 검토자
A6: 작성일 | E6: 검토일
A7: 결산일 | C7: =기본사항!C10 -> 2025-12-31
B10: 전 기 | E10: =기본사항!C10 -> 2025-12-31 | I10: 비 고
A11: ACCOUNT | B11: 전기잔액 | C11: INCREASE | D11: DECREASE | E11: PER BOOK | F11: AJE | G11: RES | H11: FINAL | I11: Refer | J11: NOTE
A12: 현금 | I12: 4110
A13: 보통예금 | I13: 4120
A14: 당좌예금 | I14: 4130
A15: 현금성자산 | I15: 4140
A16: 단기금융상품 | I16: 4150
A17: 장기금융상품 | I17: 4160
A19: 합 계 | B19: =SUM(B12:B17) -> 0 | C19: =SUM(C12:C17) -> 0 | D19: =SUM(D12:D17) -> 0 | E19: =SUM(E12:E17) -> 0 | F19: =SUM(F12:F17) -> 0 | G19: =SUM(G12:G17) -> 0 | H19: =SUM(H12:H17) -> 0
A21: ▶ 증감분석
A22: ACCOUNT | B22: 증감금액 | C22: 증감비율 | D22: 비 고
A23: 현금
A24: 보통예금
A25: 당좌예금
A26: 현금성자산
A27: 단기금융상품
A28: 장기금융상품
A31: ▶ 감사절차 (Audit Procedures)
A32: No. | B32: 감사절차 | E32: 경영진 주장 | G32: 수행여부 | H32: 조서번호 | I32: 비 고
A33: 1 | B33: [총괄표 작성 및 전기 대비 검토] 당기말 잔액을 총계정원장과 대조하고 전기말 잔액은 전기감사보고서와 대조한다. 양연도간 유의적 변동사항의 원인을 파악한다. | E33: E, C, CL
A34: 2 | B34: [현금 및 미사용수표 실사] 기말 현재 현금·미사용수표·어음을 직접 실사하여 장부잔액과 대조한다. | E34: E, C, RO
A35: 3 | B35: [금융기관 잔액조회서 발송 및 회수] 기중 잔액이 없는 계좌 포함 전 금융기관에 조회서를 발송한다. 발송·회수는 감사인이 직접 수행하며, 차입금·담보·지급보증 등도 함께 확인한다. | E35: E, RO
A36: 4 | B36: [사용제한 예금 및 장기성 예금 검토] 질권·담보 제공 예금, 사용제한 예금의 유동·비유동 분류 적정성을 확인한다. 장기성 예금의 비유동 분류 여부를 검토한다. | E36: CL
A37: 5 | B37: [은행계정 간 자금이체(Kiting) 검토] 기말 전후 은행계정 간 자금이체를 확인하여 동일 기간 내 입·출금이 정확히 반영되었는지 검토한다. 은행계정조정표상 미결항목의 적정성을 확인한다. | E37: CL, V
A38: 6 | B38: [이자수익 및 미수수익 연계 검토] 이자부 예금의 발생이자와 미수수익 계상 적정성을 확인하고 관련 손익계정과 연결하여 누락 여부를 검토한다. | E38: C, V, A
A39: 7 | B39: [기간귀속(Cut-off) 검토] 기말 전후 현금·예금 거래의 기간 귀속 적정성을 검토한다. | E39: C, V
A40: 8 | B40: [재무제표 공시사항 검토] 사용제한 예금, 담보제공 예금 등 공시사항 점검표에 따라 주석 기재 충분성을 확인한다. | E40: C, CL, U, P
A42: ▶ 감사결론
A47: ※ 본 감사조서는 「주식회사 등의 외부감사에 관한 법률」에 따라 작성되었습니다.

Sheet 유가증권
A2: =기본사항!C8 -> 주식회사 XXX | G2: 조서No. 4201
A3: 유가증권 (유동·비유동)
A4: LEAD SCHEDULE
A5: 작성자 | E5: 검토자
A6: 작성일 | E6: 검토일
A7: 결산일 | C7: =기본사항!C10 -> 2025-12-31
B10: 전 기 | E10: =기본사항!C10 -> 2025-12-31 | I10: 비 고
A11: ACCOUNT | B11: 전기잔액 | C11: INCREASE | D11: DECREASE | E11: PER BOOK | F11: AJE | G11: RES | H11: FINAL | I11: Refer | J11: NOTE
A12: 단기매매증권 | I12: 4210
A13: 매도가능증권(유동) | I13: 4220
A14: 만기보유증권(유동) | I14: 4230
A15: 매도가능증권(비유동) | I15: 4240
A16: 만기보유증권(비유동) | I16: 4250
A17: 지분법적용투자주식 | I17: 4260
A19: 합 계 | B19: =SUM(B12:B17) -> 0 | C19: =SUM(C12:C17) -> 0 | D19: =SUM(D12:D17) -> 0 | E19: =SUM(E12:E17) -> 0 | F19: =SUM(F12:F17) -> 0 | G19: =SUM(G12:G17) -> 0 | H19: =SUM(H12:H17) -> 0
A21: ▶ 증감분석
A22: ACCOUNT | B22: 증감금액 | C22: 증감비율 | D22: 비 고
A23: 단기매매증권
A24: 매도가능증권(유동)
A25: 만기보유증권(유동)
A26: 매도가능증권(비유동)
A27: 만기보유증권(비유동)
A28: 지분법적용투자주식
A31: ▶ 감사절차 (Audit Procedures)
A32: No. | B32: 감사절차 | E32: 경영진 주장 | G32: 수행여부 | H32: 조서번호 | I32: 비 고
A33: 1 | B33: [금융자산 총괄표 작성 및 전기 대비 검토] 당기말 잔액을 총계정원장과, 전기말 잔액은 전기감사보고서와 대조한다. 유의적 변동사항의 원인을 파악한다. | E33: E, C, CL
A34: 2 | B34: [금융자산 실재성 확인] 직접 보유 금융자산은 실사하고, 타처 보관·담보 제공 금융자산은 보관자에게 직접 조회하거나 보관확인서를 입수한다. 유치권·저당권·담보제공 여부를 확인한다. | E34: E, RO
A35: 3 | B35: [중요한 취득·처분 거래 검토] 기중 중요한 취득·처분 거래에 대해 거래증빙을 대사하여 기간귀속, 발생사실, 취득원가 및 처분손익의 적정성을 확인한다. | E35: O, CO, V
A36: 4 | B36: [공정가치 평가 적정성 검토] 공시가격 금융자산은 독립적으로 입수한 공시가격과 대사한다. 평가기법 적용 금융자산은 공정가치 측정 모델의 적정성을 검토한다. 평가손익이 당기손익 또는 기타포괄손익으로 적절히 반영되었는지 확인한다. | E36: V
A37: 5 | B37: [금융자산 분류 적정성 검토] 단기매매증권·매도가능증권·만기보유증권 등으로의 분류가 일반기업회계기준 제6장에 부합하는지 검토한다. 재분류가 있는 경우 그 근거와 미실현손익 처리 적정성을 확인한다. | E37: CL
A38: 6 | B38: [손상차손 검토] 손상 대상 금융자산이 모두 파악되었는지 확인하고, 손상의 객관적 증거를 검토한다. 손상차손 평가의 적정성 및 손상 회복 시 회계처리를 검토한다. | E38: V
A39: 7 | B39: [배당금 및 이자수익 검토] 배당금은 지급받을 권리 확정 시점에 당기손익 인식 여부를 확인한다. 채무증권 이자수익은 유효이자율법 적용 여부를 검토한다. | E39: O, CO, A
A40: 8 | B40: [특수관계자 거래 및 기말 전후 결산조작 검토] 특수관계자와의 금융자산 취득·처분 가액의 적정성을 확인한다. 기말 전후 취득·처분 및 환매조건부 처분에 의한 결산조작 가능성을 검토한다. | E40: E, V, CL
A41: 9 | B41: [재무제표 공시사항 검토] 공시사항 점검표에 따라 금융자산 분류, 공정가치 측정, 담보제공 현황 등의 주석 기재 충분성을 확인한다. | E41: C, CL, U, P
A43: ▶ 감사결론
A48: ※ 본 감사조서는 「주식회사 등의 외부감사에 관한 법률」에 따라 작성되었습니다.

Sheet 매출채권
A2: =기본사항!C8 -> 주식회사 XXX | G2: 조서No. 4301
A3: 매출채권 (장단기)
A4: LEAD SCHEDULE
A5: 작성자 | E5: 검토자
A6: 작성일 | E6: 검토일
A7: 결산일 | C7: =기본사항!C10 -> 2025-12-31
B10: 전 기 | E10: =기본사항!C10 -> 2025-12-31 | I10: 비 고
A11: ACCOUNT | B11: 전기잔액 | C11: INCREASE | D11: DECREASE | E11: PER BOOK | F11: AJE | G11: RES | H11: FINAL | I11: Refer | J11: NOTE
A12: 외상매출금 | I12: C310
A13: 대손충당금_매출채권 | I13: C311
A14: 받을어음 | I14: C320
A15: 장기매출채권 | I15: C330
A17: 합 계 | B17: =SUM(B12:B15) -> 0 | C17: =SUM(C12:C15) -> 0 | D17: =SUM(D12:D15) -> 0 | E17: =SUM(E12:E15) -> 0 | F17: =SUM(F12:F15) -> 0 | G17: =SUM(G12:G15) -> 0 | H17: =SUM(H12:H15) -> 0
A19: ▶ 증감분석
A20: ACCOUNT | B20: 증감금액 | C20: 증감비율 | D20: 비 고
A21: 외상매출금
A22: 대손충당금_매출채권
A23: 받을어음
A24: 장기매출채권
A27: ▶ 감사절차 (Audit Procedures)
A28: No. | B28: 감사절차 | E28: 경영진 주장 | G28: 수행여부 | H28: 조서번호 | I28: 비 고
A29: 1 | B29: [총괄표 작성 및 전기 대비 검토] 당기말 잔액을 총계정원장과, 전기말 잔액은 전기감사보고서와 대조하고 양연도간 유의적 변동원인을 파악한다. | E29: E, C, CL
A30: 2 | B30: [매출채권 명세서 검증] 거래처별 매출채권명세서를 입수하여 계산검증하고 보조부와 대조한다. 유의적·비경상적 항목을 스캔한다. | E30: C, V
A31: 3 | B31: [외상매출금 외부조회] 주요 거래처에 잔액조회서를 발송·회수한다. 조회 미회신분에 대해 대체절차를 수행한다. | E31: E, RO, V
A32: 4 | B32: [장단기 분류 및 계정 재분류 검토] 일반 상거래 외 채권 포함 여부를 조사하고 장단기 구분 적정성을 확인한다. | E32: V, CL
A33: 5 | B33: [대손충당금 적정성 검토] 연령분석표 입수 및 회수기간 분석을 실시한다. 합리적 기준에 의한 대손충당금 설정 여부와 전기와의 일관성을 확인한다. | E33: V, A
A34: 6 | B34: [받을어음 실사 및 할인·양도 검토] 보관 중인 받을어음을 실사하고, 할인·배서양도·팩토링·담보제공 채권의 제거조건 충족 여부를 검토한다. | E34: E, RO, CL
A35: 7 | B35: [Cut-off 검토] 기말 전후 제품인도 및 용역제공이 해당 기간에 적절히 반영되었는지 확인한다. | E35: RO, V
A36: 8 | B36: [외화채권 환산 검토] 외화표시 매출채권의 기말 환율 적용 및 외화환산손익 계상 적정성을 검토한다. | E36: V, A
A37: 9 | B37: [특수관계자 거래 검토] 특수관계자 매출채권 금액·조건 적정성을 확인하고 Audit Guide 3500을 참고한다. | E37: E, CL
A38: 10 | B38: [재무제표 공시사항 검토] 공시사항 점검표에 따라 대손충당금, 담보제공, 특수관계자 채권 등 주석 기재 충분성을 확인한다. | E38: C, CL, U, P
A40: ▶ 감사결론
A45: ※ 본 감사조서는 「주식회사 등의 외부감사에 관한 법률」에 따라 작성되었습니다.

Sheet 기타유동자산
A2: =기본사항!C8 -> 주식회사 XXX | G2: 조서No. 4401
A3: 기타유동자산
A4: LEAD SCHEDULE
A5: 작성자 | E5: 검토자
A6: 작성일 | E6: 검토일
A7: 결산일 | C7: =기본사항!C10 -> 2025-12-31
B10: 전 기 | E10: =기본사항!C10 -> 2025-12-31 | I10: 비 고
A11: ACCOUNT | B11: 전기잔액 | C11: INCREASE | D11: DECREASE | E11: PER BOOK | F11: AJE | G11: RES | H11: FINAL | I11: Refer | J11: NOTE
A12: 미수금 | I12: C410
A13: 미수수익 | I13: C420
A14: 선급금 | I14: C430
A15: 선급비용 | I15: C440
A16: 부가세대급금 | I16: C450
A18: 합 계 | B18: =SUM(B12:B16) -> 0 | C18: =SUM(C12:C16) -> 0 | D18: =SUM(D12:D16) -> 0 | E18: =SUM(E12:E16) -> 0 | F18: =SUM(F12:F16) -> 0 | G18: =SUM(G12:G16) -> 0 | H18: =SUM(H12:H16) -> 0
A20: ▶ 증감분석
A21: ACCOUNT | B21: 증감금액 | C21: 증감비율 | D21: 비 고
A22: 미수금
A23: 미수수익
A24: 선급금
A25: 선급비용
A26: 부가세대급금
A29: ▶ 감사절차 (Audit Procedures)
A30: No. | B30: 감사절차 | E30: 경영진 주장 | G30: 수행여부 | H30: 조서번호 | I30: 비 고
A31: 1 | B31: [총괄표 작성 및 전기 대비 검토] 당기말 잔액을 총계정원장과, 전기말 잔액은 전기감사보고서와 대조하고 유의적 변동원인을 파악한다. | E31: E, C, CL
A32: 2 | B32: [계정별 명세서 검증] 미수금·미수수익·선급금·선급비용 등 각 계정별 명세서를 입수하여 계산검증하고 보조부와 대조한다. | E32: C, V
A33: 3 | B33: [주요 항목 증빙 대조] 주요 금액에 대해 관련 증빙서류와 대조하여 거래 발생 및 금액의 타당성을 확인한다. | E33: A, E, V
A34: 4 | B34: [선급비용 기간 계산 적정성] 선급비용의 보험·임대차 등 계약 누락 없이 포함되었는지 확인하고 기간 계산의 정확성을 검증한다. 1년 이상 잔류 항목을 조사한다. | E34: C, CO
A35: 5 | B35: [회수가능성 및 대손충당금] 회수불능채권의 대손처리 여부를 확인하고 대손충당금 설정의 타당성 및 전기 대비 일관성을 검토한다. | E35: V
A36: 6 | B36: [외부조회 수행] 주요 거래처에 대한 자산이 중요할 경우 외부 확인을 수행한다. | E36: A, E, C, RO
A37: 7 | B37: [외화자산 환산 검토] 외화표시 자산의 기말 환율 적용 및 외화환산손익 계상 적정성을 검토한다. | E37: V, CL
A38: 8 | B38: [특수관계자 거래 검토] 특수관계자와의 거래 금액·조건 적정성을 확인한다. | E38: E, CL
A39: 9 | B39: [재무제표 공시사항 검토] 공시사항 점검표에 따라 주석 기재 충분성을 확인한다. | E39: C, CL, U, P
A41: ▶ 감사결론
A46: ※ 본 감사조서는 「주식회사 등의 외부감사에 관한 법률」에 따라 작성되었습니다.

Sheet 재고자산
A2: =기본사항!C8 -> 주식회사 XXX | G2: 조서No. 4501
A3: 재고자산
A4: LEAD SCHEDULE
A5: 작성자 | E5: 검토자
A6: 작성일 | E6: 검토일
A7: 결산일 | C7: =기본사항!C10 -> 2025-12-31
B10: 전 기 | E10: =기본사항!C10 -> 2025-12-31 | I10: 비 고
A11: ACCOUNT | B11: 전기잔액 | C11: INCREASE | D11: DECREASE | E11: PER BOOK | F11: AJE | G11: RES | H11: FINAL | I11: Refer | J11: NOTE
A12: 상품 | I12: C510
A13: 제품 | I13: C520
A14: 원재료 | I14: C530
A15: 재공품 | I15: C540
A16: 저장품 | I16: C550
A17: 재고자산평가충당금 | I17: C560
A19: 합 계 | B19: =SUM(B12:B17) -> 0 | C19: =SUM(C12:C17) -> 0 | D19: =SUM(D12:D17) -> 0 | E19: =SUM(E12:E17) -> 0 | F19: =SUM(F12:F17) -> 0 | G19: =SUM(G12:G17) -> 0 | H19: =SUM(H12:H17) -> 0
A21: ▶ 증감분석
A22: ACCOUNT | B22: 증감금액 | C22: 증감비율 | D22: 비 고
A23: 상품
A24: 제품
A25: 원재료
A26: 재공품
A27: 저장품
A28: 재고자산평가충당금
A31: ▶ 감사절차 (Audit Procedures)
A32: No. | B32: 감사절차 | E32: 경영진 주장 | G32: 수행여부 | H32: 조서번호 | I32: 비 고
A33: 1 | B33: [총괄표 작성 및 전기 대비 검토] 당기말 잔액을 총계정원장과, 전기말 잔액은 전기감사보고서와 대조하고 유의적 변동원인을 파악한다. | E33: E, C, CL
A34: 2 | B34: [재고자산 수불부 검증] 수불부를 계산검증하고 재무상태표·손익계산서·제조원가명세서 관련 계정과 연결한다. | E34: C, V
A35: 3 | B35: [재고자산 실사 입회] 실사입회 절차(E100)를 참조하여 수행한다. 실사집계표와 수불부 수량을 연결한다. | E35: E, RO, V
A36: 4 | B36: [분석적 검토] 매출액 대비 재고비율, 재고증감율, 재고자산 회전율을 분석하고 비정상적 변동을 조사한다. | E36: E, C
A37: 5 | B37: [단가 적정성 검토] 수불부 단가를 구입증빙과 대사하고, 전기 단가와 비교하여 비정상적 변동을 조사한다. | E37: V, A
A38: 6 | B38: [재고자산 평가(저가법) 검토] 파손·진부화·장기체화 재고의 순실현가능가액과 장부금액을 비교하고 평가손실 계상 적정성을 검토한다. | E38: V
A39: 7 | B39: [Cut-off 검토] 기말 전후 출고증·입고증을 매입보조부와 대조하여 기간귀속 적정성을 확인한다. | E39: CO
A40: 8 | B40: [담보 제공 재고 확인] 담보 또는 양도담보로 제공된 재고자산 유무를 확인하고 주석 공시 여부를 검토한다. | E40: RO
A41: 9 | B41: [특수관계자 거래 검토] 특수관계자와의 거래가격 타당성(부당한 고가·저가 여부)을 파악한다. | E41: E, CL
A42: 10 | B42: [재무제표 공시사항 검토] 공시사항 점검표에 따라 재고자산 평가방법, 담보제공 현황 등 주석 기재 충분성을 확인한다. | E42: C, CL, U, P
A44: ▶ 감사결론
A49: ※ 본 감사조서는 「주식회사 등의 외부감사에 관한 법률」에 따라 작성되었습니다.

Sheet 유형자산
A2: =기본사항!C8 -> 주식회사 XXX | G2: 조서No. 4701
A3: 유형자산
A4: LEAD SCHEDULE
A5: 작성자 | E5: 검토자
A6: 작성일 | E6: 검토일
A7: 결산일 | C7: =기본사항!C10 -> 2025-12-31
B10: 전 기 | E10: =기본사항!C10 -> 2025-12-31 | I10: 비 고
A11: ACCOUNT | B11: 전기잔액 | C11: INCREASE | D11: DECREASE | E11: PER BOOK | F11: AJE | G11: RES | H11: FINAL | I11: Refer | J11: NOTE
A12: 토지 | I12: C710
A13: 건물 | I13: C720
A14: 감가상각누계액_건물 | I14: C721
A15: 구축물 | I15: C730
A16: 기계장치 | I16: C740
A17: 감가상각누계액_기계 | I17: C741
A18: 차량운반구 | I18: C750
A19: 비품 | I19: C760
A20: 건설중인자산 | I20: C770
A22: 합 계 | B22: =SUM(B12:B20) -> 0 | C22: =SUM(C12:C20) -> 0 | D22: =SUM(D12:D20) -> 0 | E22: =SUM(E12:E20) -> 0 | F22: =SUM(F12:F20) -> 0 | G22: =SUM(G12:G20) -> 0 | H22: =SUM(H12:H20) -> 0
A24: ▶ 증감분석
A25: ACCOUNT | B25: 증감금액 | C25: 증감비율 | D25: 비 고
A26: 토지
A27: 건물
A28: 감가상각누계액_건물
A29: 구축물
A30: 기계장치
A31: 감가상각누계액_기계
A32: 차량운반구
A33: 비품
A34: 건설중인자산
A37: ▶ 감사절차 (Audit Procedures)
A38: No. | B38: 감사절차 | E38: 경영진 주장 | G38: 수행여부 | H38: 조서번호 | I38: 비 고
A39: 1 | B39: [총괄표 작성 및 전기 대비 검토] 유형자산 장부가액 변동요약표를 입수·분석하고 당기말은 총계정원장, 전기말은 전기감사보고서와 대조한다. | E39: E, C, CL
A40: 2 | B40: [권리증서 확인 (실재성·소유권)] 등기부등본·등록원부 등을 획득하여 실재성, 소유권 및 담보제공 등 소유권 제한사항을 확인한다. | E40: E, RO
A41: 3 | B41: [감가상각비 적정성 검토] 상각방법·내용연수·상각률의 계속 적용 여부를 검토하고 감가상각비를 재계산한다. 방법 변경 시 타당성과 재무제표 영향을 확인한다. | E41: C, V, A
A42: 4 | B42: [취득 자산 검증] 당기 취득 자산에 대해 계약서·세금계산서·등기부등본을 확인하고 소유권 귀속을 검토한다. | E42: E, RO, V
A43: 5 | B43: [처분·폐기 검토] 처분명세서를 입수하여 처분가격 적정성을 검토하고 처분손익 등 관련 손익계정과 연결한다. | E43: A
A44: 6 | B44: [손상차손 검토] 손상징후 자산에 대해 회수가능가액을 산정하고 손상차손 계상 및 회계처리 적정성을 검토한다. | E44: V, A
A45: 7 | B45: [건설중인 자산 검토] 당기 지출액, 취득 약정액, 차입원가 자본화 적정성을 검토하고 완공 자산의 대체 회계처리를 확인한다. | E45: A, V
A46: 8 | B46: [수익적·자본적 지출 구분] 수선비 성격 지출의 자산화 여부 및 구분 기준의 타당성과 계속성을 검토한다. | E46: A
A47: 9 | B47: [특수관계자 거래 검토] 특수관계자와의 유형자산 거래 가격 적정성을 확인한다. | E47: E, CL
...

Sheet 무형자산
A2: =기본사항!C8 -> 주식회사 XXX | G2: 조서No. 4801
A3: 무형자산
A4: LEAD SCHEDULE
A5: 작성자 | E5: 검토자
A6: 작성일 | E6: 검토일
A7: 결산일 | C7: =기본사항!C10 -> 2025-12-31
B10: 전 기 | E10: =기본사항!C10 -> 2025-12-31 | I10: 비 고
A11: ACCOUNT | B11: 전기잔액 | C11: INCREASE | D11: DECREASE | E11: PER BOOK | F11: AJE | G11: RES | H11: FINAL | I11: Refer | J11: NOTE
A12: 영업권 | I12: C810
A13: 산업재산권 | I13: C820
A14: 개발비 | I14: C830
A15: 기타무형자산 | I15: C840
A16: 상각누계액 | I16: C841
A18: 합 계 | B18: =SUM(B12:B16) -> 0 | C18: =SUM(C12:C16) -> 0 | D18: =SUM(D12:D16) -> 0 | E18: =SUM(E12:E16) -> 0 | F18: =SUM(F12:F16) -> 0 | G18: =SUM(G12:G16) -> 0 | H18: =SUM(H12:H16) -> 0
A20: ▶ 증감분석
A21: ACCOUNT | B21: 증감금액 | C21: 증감비율 | D21: 비 고
A22: 영업권
A23: 산업재산권
A24: 개발비
A25: 기타무형자산
A26: 상각누계액
A29: ▶ 감사절차 (Audit Procedures)
A30: No. | B30: 감사절차 | E30: 경영진 주장 | G30: 수행여부 | H30: 조서번호 | I30: 비 고
A31: 1 | B31: [총괄표 작성 및 전기 대비 검토] 무형자산 장부가액 변동요약표를 입수·분석하고 당기말은 총계정원장, 전기말은 전기감사보고서와 대조한다. | E31: E, C, CL
A32: 2 | B32: [명세서 검증 및 소유권 확인] 무형자산명세서를 계산검증하고 보조부와 대조한다. 등록증·계약서 등으로 소유권 및 제한사항을 확인한다. | E32: C, V, RO
A33: 3 | B33: [상각비 적정성 검토] 상각방법·내용연수·잔존가액의 계속 적용 여부를 검토하고 상각비를 재계산한다. 비한정 내용연수 자산의 타당성을 검토한다. | E33: V, A
A34: 4 | B34: [처분 검토] 처분명세서를 입수하여 처분가격 적정성을 검토하고 관련 손익계정과 연결한다. | E34: E, V, A
A35: 5 | B35: [손상차손 검토] 손상징후 무형자산에 대해 회수가능가액을 산정하고 손상차손 계상 및 회계처리 적정성을 검토한다. | E35: V
A36: 6 | B36: [자산 인식 요건 충족 여부] 후속적 지출이 자산 인식 요건에 해당하는지 검토하고, 과거 비용 처리된 지출이 자산화되지 않았는지 확인한다. | E36: V, CL
A37: 7 | B37: [영업권·염가매수차익 검토] 사업결합 관련 영업권과 염가매수차익의 회계처리 적정성을 검토한다.(일반기업회계기준 제12장) | E37: V
A38: 8 | B38: [재무제표 공시사항 검토] 공시사항 점검표에 따라 상각방법, 내용연수, 손상차손 등 주석 기재 충분성을 확인한다. | E38: C, CL, U, P
A40: ▶ 감사결론
A45: ※ 본 감사조서는 「주식회사 등의 외부감사에 관한 법률」에 따라 작성되었습니다.

Sheet 기타비유동자산
A2: =기본사항!C8 -> 주식회사 XXX | G2: 조서No. 4901
A3: 기타비유동자산
A4: LEAD SCHEDULE
A5: 작성자 | E5: 검토자
A6: 작성일 | E6: 검토일
A7: 결산일 | C7: =기본사항!C10 -> 2025-12-31
B10: 전 기 | E10: =기본사항!C10 -> 2025-12-31 | I10: 비 고
A11: ACCOUNT | B11: 전기잔액 | C11: INCREASE | D11: DECREASE | E11: PER BOOK | F11: AJE | G11: RES | H11: FINAL | I11: Refer | J11: NOTE
A12: 장기매출채권 | I12: C910
A13: 장기대여금 | I13: C920
A14: 보증금 | I14: C930
A15: 기타비유동자산 | I15: C940
A17: 합 계 | B17: =SUM(B12:B15) -> 0 | C17: =SUM(C12:C15) -> 0 | D17: =SUM(D12:D15) -> 0 | E17: =SUM(E12:E15) -> 0 | F17: =SUM(F12:F15) -> 0 | G17: =SUM(G12:G15) -> 0 | H17: =SUM(H12:H15) -> 0
A19: ▶ 증감분석
A20: ACCOUNT | B20: 증감금액 | C20: 증감비율 | D20: 비 고
A21: 장기매출채권
A22: 장기대여금
A23: 보증금
A24: 기타비유동자산
A27: ▶ 감사절차 (Audit Procedures)
A28: No. | B28: 감사절차 | E28: 경영진 주장 | G28: 수행여부 | H28: 조서번호 | I28: 비 고
A29: 1 | B29: [총괄표 작성 및 전기 대비 검토] 당기말 잔액을 총계정원장과, 전기말 잔액은 전기감사보고서와 대조하고 유의적 변동원인을 파악한다. | E29: E, C, CL
A30: 2 | B30: [명세서 검증] 기타비유동자산명세서를 입수하여 계산검증하고 보조부와 대조한다. | E30: C, V
A31: 3 | B31: [외부확인 수행] 주요 거래처에 대한 자산이 중요할 경우 외부 확인을 수행한다. | E31: A, E, RO
A32: 4 | B32: [주요 항목 증빙 대조] 주요 금액에 대해 관련 증빙서류와 대조하여 거래 발생 및 금액의 타당성을 확인한다. | E32: E, C, V
A33: 5 | B33: [회수가능성 및 대손충당금] 회수불능자산의 대손처리 여부를 확인하고 대손충당금 설정의 타당성 및 계속성을 검토한다. | E33: V
A34: 6 | B34: [현재가치 평가 적정성] 현재가치 평가 대상 자산의 할인율·할인차금 계산 적정성을 검증하고 관련 손익계정 반영 여부를 확인한다. | E34: V, A
A35: 7 | B35: [관련 손익계정 연계 검토] 기타비유동자산 관련 발생 손익계정이 적정하게 계상되었는지 확인한다. | E35: C, V, A
A36: 8 | B36: [특수관계자 거래 검토] 특수관계자와의 거래 금액·조건 적정성을 확인한다. | E36: E, CL
A37: 9 | B37: [재무제표 공시사항 검토] 공시사항 점검표에 따라 주석 기재 충분성을 확인한다. | E37: C, CL, U, P
A39: ▶ 감사결론
A44: ※ 본 감사조서는 「주식회사 등의 외부감사에 관한 법률」에 따라 작성되었습니다.
