Workbook
Name ____TB112: #REF!
Name ____TB115: #REF!
Name ____TB124: #REF!
Name ____TB125: #REF!
Name ____TB126: #REF!
Name ____TB131: #REF!
Name ____TB132: #REF!
Name ____TB211: #REF!
Name ____TB213: #REF!
Name ____TB214: #REF!
Name ____TB215: #REF!
Name ____TB221: #REF!
Name ____TB2210: #REF!
Name ____TB222: #REF!
Name ____TB223: #REF!
Name ____TB224: #REF!
Name ____TB225: #REF!
Name ____TB227: #REF!
Name ____TB229: #REF!
Name ____TB311: #REF!
Name ____TB313: #REF!
Name ____TB317: #REF!
Name ____TB318: #REF!
Name ____TB319: #REF!
Name ____TB322: #REF!
Name ____TB323: #REF!
Name ____TB324: #REF!
Name ____TB325: #REF!
Name ____TB401: #REF!
Name ____TB402: #REF!
Name ____TB403: #REF!
Name ____TB404: #REF!
Name ____TB405: #REF!
Name ____TB510: #REF!
Name ____TB511: #REF!
Name ____TB601: #REF!
Name ____TB604: #REF!
Name ____TB605: #REF!
Name ____TB811: #REF!
Name ____TB812: #REF!
Name ____TB813: #REF!
Name ____TB814: #REF!
Name ____TB820: #REF!
Name ____TBI1001: #REF!
Name ____TBI1002: #REF!
Name ____TBI1003: #REF!
Name ____TBI1004: #REF!
Name ____TBI1005: #REF!
Name ____TBI102: #REF!
Name ____TBI1200: #REF!
Name ____TBI403: #REF!
Name ____TBI425: #REF!
Name ____TBI603: #REF!
Name ____TBI604: #REF!
Name ____TBI605: #REF!
Name ____TBI606: #REF!
Name ____TBI607: #REF!
Name ____TBI608: #REF!
Name ____TBI609: #REF!
Name ____TBI611: #REF!

Sheet 기본사항
A2: 감사조서 기본사항
A3: Basic Information of Working Papers
A5: ※ 아래 항목을 입력하면 모든 감사조서에 자동으로 반영됩니다.
B7: 항 목 | C7: 입력값 | D7: 비 고
B8: 회사명 | C8: 주식회사 경남제약 | D8: 피감사회사의 정확한 법인명을 입력하세요
B9: 감사기간 시작일 | C9: 46023 | D9: 예: 2025-01-01
B10: 감사기간 종료일 | C10: 46203 | D10: 예: 2025-12-31 ← 각 시트 결산일에 자동 반영
B11: 작성자 | C11: 이병하 | D11: 감사조서 작성 담당자 성명
B12: 작성일 | C12: 46227 | D12: 작성일 (예: 2025-01-15)
C13: 이광우
B14: 검토일 | C14: 46227
A17: ▶ 셀 참조 정보 (각 리드스케줄 시트에서 아래 셀을 참조합니다)
B18: 기본사항!C8 | C18: → 회사명
B19: 기본사항!C9 | C19: → 감사기간 시작일
B20: 기본사항!C10 | C20: → 감사기간 종료일 (결산일 / 당기 헤더 자동 반영)
B21: 기본사항!C11 | C21: → 작성자 → 각 시트 행5 작성자란 자동 반영
B22: 기본사항!C12 | C22: → 작성일 → 각 시트 행6 작성일란 자동 반영
B23: 기본사항!C13 | C23: → 검토자 → 각 시트 행5 검토자란 자동 반영
B24: 기본사항!C14 | C24: → 검토일 → 각 시트 행6 검토일란 자동 반영

Sheet 목차
A2: =기본사항!C8 -> 주식회사 경남제약
A3: 감사조서 목차 (Index of Working Papers)
A4: 결산일: 2025년 12월 31일
B6: 조서번호 | C6: 계정과목 | D6: 담당자 | E6: 비고
B7: 4201 | C7: =HYPERLINK("#현예금!A1","현금및현금성자산") -> 현금및현금성자산
B8: 4301 | C8: =HYPERLINK("#매출채권!A1","매출채권") -> 매출채권
B9: 4401 | C9: =HYPERLINK("#재고자산!A1","재고자산") -> 재고자산
B10: 4501 | C10: =HYPERLINK("#유형자산!A1","유형자산") -> 유형자산
B11: 4601 | C11: =HYPERLINK("#장단기차입금!A1","장단기차입금") -> 장단기차입금
B12: 4701 | C12: =HYPERLINK("#매출!A1","매출") -> 매출
B13: 4801 | C13: =HYPERLINK("#판관비!A1","판매비및관리비") -> 판매비및관리비
A16: ※ 색상 범례: 파란 글씨 = 수식/링크 │ 보라 글씨 = 감사분석 체크항목 │ 노란 배경 = 분석 포인트 섹션

Sheet 회사담당자
A1: 계정과목 | B1: 담당자
A2: Ⅰ.유동자산
A3: 현금및현금성자산 | B3: 서정아
A4: 단기투자자산_매도가능증권 | B4: 서정아
A5: 단기금융상품 | B5: 김규리
A6: 매출채권 | B6: 김규리
A7: 매출채권대손충당금 | B7: 김규리
A8: 단기대여금 | B8: 박재윤
A9: 단기대여금대손충당금 | B9: 김규리
A10: 미수수익 | B10: 김규리
A11: 미수수익대손충당금 | B11: 김규리
A12: 미수금 | B12: 박재윤
A13: 미수금대손충당금 | B13: 김규리
A14: 선급금 | B14: 박재윤
... A25: 보증금 | B25: 박재윤
A26: 자산총계
A27: Ⅰ.유동부채
A28: 매입채무 | B28: 김규리
A29: 미지급금 | B29: 박재윤
A30: 예수금 | B30: 박재윤
A31: 임대보증금 | B31: 박재윤
A32: 일반선수금 | B32: 서정아
A33: 단기차입금 | B33: 김규리
A34: 미지급비용 | B34: 김규리
A35: 유동성장기채무 | B35: 김규리
A36: 환불부채 | B36: 신희조
A37: 전환사채 | B37: 서정아
A38: 전환권조정 | B38: 서정아
A39: 전환사채할인발행차금 | B39: 서정아
... A43: 단기리스부채 | B43: 김규리
A44: Ⅱ.고정부채
A45: 퇴직급여충당금 | B45: 김규리
A46: 국민연금전환금 | B46: 김규리
A47: 퇴직연금예치금 | B47: 김규리
A48: 장기미지급비용 | B48: 김규리
A49: 수입보증금 | B49: 김규리
A50: 장기리스부채 | B50: 김규리
A51: 이연법인세부채
A52: Ⅰ.자본금
A53: Ⅱ.자본잉여금
...

Sheet 세부assign
A1: 삼덕회계법인
B2: Client | C2: Period-end | D2: Prepared by | E2: Date | F2: reviewed by | G2: Date | H2: no
B3: 경남제약 | C3: 46022 | D3: 박재우 | E3: 46160 | F3: 이광우
A4: 1. 계획단계
B5: 구분 | C5: 이광우(담당이사) | D5: 박재우(책임회계사) | E5: 오세훈 | F5: 이양수 | G5: 이병하
B6: 일반조서 | C6: reviewer | D6: v
A8: 2. 전기조서 열람
B9: 구분 | C9: 이광우(담당이사) | D9: 박재우(책임회계사) | E9: 오세훈 | F9: 이양수 | G9: 이병하
B10: N/A | C10: v | D10: v | F10: v
A12: 3. 기초잔액, 반기검토, 중간감사, 내부회계 및 기말감사
B13: <BS계정>
B14: 구분 | C14: 이광우(담당이사) | D14: 박재우(책임회계사) | E14: 오세훈 | F14: 이양수 | G14: 이병하 | H14: 당기 | I14: 전기 | K14: 담당회계사 assignment에 대한 의견
B15: 일반조서(내부회계 entity level 포함) | C15: reviewer
B16: Ⅰ.유동자산 | I16: 79454666283
B17: 현금및현금성자산 | C17: reviewer | F17: v | I17: 6254383438
B18: 단기투자자산_매도가능증권 | C18: reviewer | F18: v | I18: 8735108945
B19: 단기금융상품 | C19: reviewer | F19: v | I19: 36150000000
B20: 매출채권 | C20: v | I20: 15867318853
B21: 매출채권대손충당금 | C21: v | I21: -795929614
B22: 단기대여금 | C22: reviewer | F22: v | I22: 163786391
B23: 단기대여금대손충당금 | C23: reviewer | F23: v | I23: -163786391
B24: 미수수익 | C24: reviewer | F24: v | I24: 126417893
B25: 미수수익대손충당금 | C25: reviewer | F25: v | I25: -57656091
B26: 미수금 | C26: reviewer | F26: v | I26: 32937015
B27: 미수금대손충당금 | C27: reviewer | F27: v | I27: -11340130
B28: 선급금 | C28: reviewer | E28: v | I28: 695880535
B29: 선급금대손충당금 | C29: reviewer | E29: v | I29: -329007400
B30: 선급비용 | C30: reviewer | F30: v | I30: 147694361
B31: 선급법인세 | C31: reviewer | D31: v | I31: 236809590
B32: 2)재고자산 | C32: reviewer | E32: v | I32: 12402048888
B33: Ⅱ.비유동자산 | I33: 76335209653
B34: 관계회사/종속기업 | C34: reviewer | D34: v | I34: 661965537
B35: 매도가능증권 | C35: reviewer | F35: v | I35: 4299455796
B36: 투자부동산 | C36: reviewer | G36: v | I36: 35949802624
B37: 2)유형자산 | C37: reviewer | G37: v | I37: 35068472967
B38: 3)무형자산 | C38: reviewer | G38: v | I38: 210052492
B39: 보증금 | C39: reviewer | G39: v | I39: 145460237
B40: 자산총계 | C40: reviewer | I40: 155789875936
B41: Ⅰ.유동부채 | I41: 46235923932
B42: 매입채무 | C42: reviewer | E42: v | I42: 5626467193
...

Sheet 데이터개요_계정별
A1: 계정명 | B1: 전표건수(차) | C1: 차변합계 | D1: 평균금액(차) | E1: 표준편차(차) | F1: 전표건수(대) | G1: 대변합계 | H1: 평균금액(대) | I1: 표준편차(대)
A2: 제예금(보통예금) | B2: 4873 | C2: 178765514081 | D2: 36684899 | E2: 6.8106667e+08 | F2: 305 | G2: 177618949084 | H2: 5.8235721e+08 | I2: 2.4725272e+09
A3: 외상매출금 | B3: 37687 | C3: 36125421395 | D3: 958564.53 | E3: 9540992.8 | F3: 42914 | G3: 34855788099 | H3: 812224.17 | I3: 6707196.5
A4: 유동성장기채무 | B4: 2 | C4: 28000000000 | D4: 14000000000 | E4: 1.4142136e+10 | F4: 0 | G4: 0 | H4: 0 | I4: 0
A5: 단기금융상품_MMF | B5: 4 | C5: 27500000000 | D5: 6875000000 | E5: 1.0411751e+10 | F5: 3 | G5: 27500000000 | H5: 9.1666667e+09 | I5: 1.2881123e+10
A6: 제품(공장) | B6: 12 | C6: 22781868956 | D6: 1.8984891e+09 | E6: 1.8262229e+09 | F6: 9 | G6: 21198423626 | H6: 2.3553804e+09 | I6: 1.7469389e+09
A7: 재공품 | B7: 26 | C7: 22717599038 | D7: 8.7375381e+08 | E7: 7.4382873e+09 | F7: 12 | G7: 22781868956 | H7: 1.8984891e+09 | I7: 1.8262229e+09
A8: 제품매출원가 | B8: 6 | C8: 21089217771 | D8: 3.5148696e+09 | E8: 2.0635044e+08 | F8: 0 | G8: 0 | H8: 0 | I8: 0
A9: 외상매입금 | B9: 465 | C9: 19370010895 | D9: 41655937 | E9: 74464779 | F9: 455 | G9: 19414695277 | H9: 42669660 | I9: 79581884
A10: 신용카드 | B10: 35721 | C10: 15856154077 | D10: 443888.86 | E10: 1203637.2 | F10: 349 | G10: 15508340473 | H10: 44436506 | I10: 1.0568012e+08
A11: 미지급금(거래처) | B11: 3653 | C11: 13901776663 | D11: 3805578.1 | E11: 52565130 | F11: 3640 | G11: 14030441886 | H11: 3854517 | I11: 52778206
A12: 외주가공비(제조) | B12: 149 | C12: 13545027100 | D12: 90906222 | E12: 98356764 | F12: 11 | G12: 13545027100 | H12: 1231366100 | I12: 8.5963968e+09
A13: 투자부동산_건물 | B13: 3 | C13: 12292305202 | D13: 4.0974351e+09 | E13: 6.1057633e+09 | F13: 4 | G13: 0 | H13: 0 | I13: 1.7607413e+08
... A313: 제품_타계정대체액 | B313: 29 | C313: -1049958080 | D313: -36205451 | E313: 1.0809207e+08 | F313: 0 | G313: 0 | H313: 0 | I313: 0

Sheet 4600_투자부동산
A2: =기본사항!C8 -> 주식회사 경남제약 | G2: 조서No. 4601
A3: 투자부동산
A4: LEAD SCHEDULE
A5: 작성자 | C5: =기본사항!C11 -> 이병하 | E5: 검토자 | G5: =기본사항!C13 -> 이광우
A6: 작성일 | C6: =기본사항!C12 -> 46227 | E6: 검토일 | G6: =기본사항!C14 -> 46227
A7: 결산일 | C7: =기본사항!C10 -> 46203
A10: 취득원가 | E10: =기본사항!C10 -> 46203 | I10: 비 고
A11: ACCOUNT | B11: 전기잔액 | C11: INCREASE | D11: DECREASE | E11: PER BOOK | F11: AJE | G11: RES | H11: FINAL | I11: Refer | J11: NOTE
A12: 투자부동산_토지 | B12: 24702221753 | C12: =IFERROR(_xlfn.XLOOKUP(A12,데이터개요_계정별!$A$2:$A$400,데이터개요_계정별!$C$2:$C$400,,0,),0) -> 4280784678 | D12: ='4600_투자부동산_매각예정자산대체'!E37 -> 7072519926 | E12: =B12+C12-D12 -> 21910486505 | H12: =E12+F12+G12 -> 21910486505
A13: 투자부동산_건물 | B13: 4713606359 | C13: =IFERROR(_xlfn.XLOOKUP(A13,데이터개요_계정별!$A$2:$A$400,데이터개요_계정별!$C$2:$C$400,,0,),0) -> 12292305202 | D13: ='4600_투자부동산_매각예정자산대체'!E38 -> 11147763220 | E13: =B13+C13-D13 -> 5858148341 | H13: =E13+F13+G13 -> 5858148341
A14: 투자부동산_건설중인자산 | B14: 10503197992 | C14: =IFERROR(_xlfn.XLOOKUP(A14,데이터개요_계정별!$A$2:$A$400,데이터개요_계정별!$C$2:$C$400,,0,),0) -> 644565228 | D14: =IFERROR(_xlfn.XLOOKUP(A14,데이터개요_계정별!$A$2:$A$400,데이터개요_계정별!$G$2:$G$400,,0,),0) -> 11147763220 | E14: =B14+C14-D14 -> 0 | H14: =E14+F14+G14 -> 0
C15: `
A18: 합 계 | B18: =SUM(B12:B16) -> 39919026104 | C18: =SUM(C12:C16) -> 17217655108 | D18: =SUM(D12:D16) -> 29368046366 | E18: =SUM(E12:E16) -> 27768634846 | F18: =SUM(F12:F16) -> 0 | G18: =SUM(G12:G16) -> 0 | H18: =SUM(H12:H16) -> 27768634846
A20: 감가상각누계액 | I20: 비 고
A21: ACCOUNT | B21: 전기잔액 | C21: INCREASE | D21: DECREASE | E21: PER BOOK | F21: AJE | G21: RES | H21: FINAL | I21: Refer | J21: NOTE
A22: 투자부동산_건물감가상각누계액 | B22: -864161100 | C22: =-IFERROR(_xlfn.XLOOKUP(A22,데이터개요_계정별!$A$2:$A$400,데이터개요_계정별!$G$2:$G$400,,0,),0) -> -374490987 | D22: =-'4600_투자부동산_매각예정자산대체'!C37 -> -67022507 | E22: =B22+C22-D22 -> -1171629580 | H22: =E22+F22+G22 -> -1171629580 | I22: C720
A24: 손상차손누계액 | I24: 비 고
A25: ACCOUNT | B25: 전기잔액 | C25: INCREASE | D25: DECREASE | E25: PER BOOK | F25: AJE | G25: RES | H25: FINAL | I25: Refer | J25: NOTE
A26: 투자부동산_건물 손상차손누계액 | B26: 0 | C26: =-IFERROR(_xlfn.XLOOKUP(A26,데이터개요_계정별!$A$2:$A$400,데이터개요_계정별!$G$2:$G$400,,0,),0) -> -3105062380 | D26: =C26 -> -3105062380 | E26: =B26+C26-D26 -> 0 | H26: =E26+F26+G26 -> 0 | I26: C720
A27: 투자부동산_건설중인자산 손상차손누계액 | B27: -3105062380 | C27: =-IFERROR(_xlfn.XLOOKUP(A27,데이터개요_계정별!$A$2:$A$400,데이터개요_계정별!$G$2:$G$400,,0,),0) -> 3105062380 | D27: =-IFERROR(_xlfn.XLOOKUP(A27,데이터개요_계정별!$A$2:$A$300,데이터개요_계정별!$C$2:$C$300,,0,),0) -> 0 | E27: =B27+C27-D27 -> 0
A29: 증감 구분
A30: ACCOUNT | B30: 증가 | E30: 감소
B31: 취득 | C31: 대체 | D31: 합계 | E31: 처분 | F31: 대체 | G31: 합계
A32: 투자부동산_토지 | B32: =SUMIFS('4600_투자부동산_증가'!$G$8:$G$100,'4600_투자부동산_증가'!$E$8:$E$100,'4600_투자부동산'!A32,'4600_투자부동산_증가'!$W$8:$W$100,'4600_투자부동산'!$B$31) -> 0 | C32: =SUMIFS('4600_투자부동산_증가'!$G$8:$G$100,'4600_투자부동산_증가'!$E$8:$E$100,'4600_투자부동산'!A32,'4600_투자부동산_증가'!$W$8:$W$100,'4600_투자부동산'!$C$31) -> 4280784678 | D32: =B32+C32 -> 4280784678 | E32: =SUMIFS('4600_투자부동산_감소'!$H$8:$H$40,'4600_투자부동산_감소'!$E$8:$E$40,'4600_투자부동산'!A32,'4600_투자부동산_감소'!$W$8:$W$40,'4600_투자부동산'!$E$31) -> 0 | F32: =SUMIFS('4600_투자부동산_감소'!$H$8:$H$40,'4600_투자부동산_감소'!$E$8:$E$40,'4600_투자부동산'!A32,'4600_투자부동산_감소'!$W$8:$W$40,'4600_투자부동산'!$F$31) -> 0 | G32: =SUM(E32:F32) -> 0 | H32: =D32=C12 -> TRUE | I32: =G32=D12 -> FALSE
A33: 투자부동산_건물 | B33: =SUMIFS('4600_투자부동산_증가'!$G$8:$G$100,'4600_투자부동산_증가'!$E$8:$E$100,'4600_투자부동산'!A33,'4600_투자부동산_증가'!$W$8:$W$100,'4600_투자부동산'!$B$31) -> 0 | C33: =SUMIFS('4600_투자부동산_증가'!$G$8:$G$100,'4600_투자부동산_증가'!$E$8:$E$100,'4600_투자부동산'!A33,'4600_투자부동산_증가'!$W$8:$W$100,'4600_투자부동산'!$C$31) -> 12292305202 | D33: =B33+C33 -> 12292305202 | E33: =SUMIFS('4600_투자부동산_감소'!$H$8:$H$40,'4600_투자부동산_감소'!$E$8:$E$40,'4600_투자부동산'!A33,'4600_투자부동산_감소'!$W$8:$W$40,'4600_투자부동산'!$E$31) -> 0 | F33: =SUMIFS('4600_투자부동산_감소'!$H$8:$H$40,'4600_투자부동산_감소'!$E$8:$E$40,'4600_투자부동산'!A33,'4600_투자부동산_감소'!$W$8:$W$40,'4600_투자부동산'!$F$31) -> 0 | G33: =SUM(E33:F33) -> 0 | H33: =D33=C13 -> TRUE | I33: =G33=D13 -> FALSE
A34: 투자부동산_건설중인자산 | B34: =SUMIFS('4600_투자부동산_증가'!$G$8:$G$100,'4600_투자부동산_증가'!$E$8:$E$100,'4600_투자부동산'!A34,'4600_투자부동산_증가'!$W$8:$W$100,'4600_투자부동산'!$B$31) -> 644565228 | C34: =SUMIFS('4600_투자부동산_증가'!$G$8:$G$100,'4600_투자부동산_증가'!$E$8:$E$100,'4600_투자부동산'!A34,'4600_투자부동산_증가'!$W$8:$W$100,'4600_투자부동산'!$C$31) -> 0 | D34: =B34+C34 -> 644565228 | E34: =SUMIFS('4600_투자부동산_감소'!$H$8:$H$40,'4600_투자부동산_감소'!$E$8:$E$40,'4600_투자부동산'!A34,'4600_투자부동산_감소'!$W$8:$W$40,'4600_투자부동산'!$E$31) -> 0 | F34: =SUMIFS('4600_투자부동산_감소'!$H$8:$H$40,'4600_투자부동산_감소'!$E$8:$E$40,'4600_투자부동산'!A34,'4600_투자부동산_감소'!$W$8:$W$40,'4600_투자부동산'!$F$31) -> 11147763220 | G34: =SUM(E34:F34) -> 11147763220 | H34: =D34=C14 -> TRUE | I34: =G34=D14 -> TRUE
A35: 합 계 | B35: =SUM(B32:B34) -> 644565228 | C35: =SUM(C32:C34) -> 16573089880 | D35: =SUM(D32:D34) -> 17217655108 | E35: =SUM(E32:E34) -> 0 | F35: =SUM(F32:F34) -> 11147763220 | G35: =SUM(G32:G34) -> 11147763220
A37: 대체증감 | B37: 부동산_건설중인자산에서 | C37: 유형자산에서 | D37: 합계 | F37: 대체감소 | G37: 투자부동산_토지로 | H37: 투자부동산_건물로 | I37: 매각예정자산으로 | J37: 합계
A38: 투자부동산_토지 | C38: ='4600_투자부동산_증가'!G11 -> 4280784678 | D38: =SUM(B38:C38) -> 4280784678 | E38: =D38=D32 -> TRUE | F38: 투자부동산_토지 | I38: ='4600_투자부동산_감소'!H12 -> 7072519926 | J38: =SUM(G38:I38) -> 7072519926
A39: 투자부동산_건물 | B39: ='4600_투자부동산_증가'!G17 -> 11147763220 | C39: ='4600_투자부동산_증가'!G18+'4600_투자부동산_증가'!G19 -> 1144541982 | D39: =SUM(B39:C39) -> 12292305202 | E39: =D39=D33 -> TRUE | F39: 투자부동산_건물 | I39: ='4600_투자부동산_감소'!H21 -> 11147763220 | J39: =SUM(G39:I39) -> 11147763220
A40: 투자부동산_건설중인자산 | D40: =SUM(B40:C40) -> 0 | F40: 투자부동산_건설중인자산 | H40: =F34 -> 11147763220 | J40: =SUM(G40:I40) -> 11147763220
A41: 투자부동산_건물감가상각누계액 | C41: ='4700_유형자산'!H78 -> -225729098 | D41: =SUM(B41:C41) -> -225729098
F42: 투자부동산_건물 손상차손누계액 | I42: =D26 -> -3105062380 | J42: =SUM(G42:I42) -> -3105062380
B43: =SUM(B38:B39) -> 11147763220 | C43: =SUM(C38:C39) -> 5425326660 | D43: =SUM(D38:D39) -> 16573089880 | G43: =SUM(G38:G41) -> 0 | H43: =SUM(H38:H42) -> 11147763220 | I43: =SUM(I38:I42) -> 15115220766 | J43: =SUM(J38:J42) -> 26262983986
B44: 유형자산에서 대체된 금액은 신규로 임대계약이 체결된 토지.건물로 임대차계약서 확인
B45: 투자부동산_건물상각비 | C45: =C22-C41 -> -148761889
A46: ▶ 증감분석
A47: ACCOUNT | B47: 증감금액 | C47: 증감비율 | D47: 비 고
A48: 투자부동산_토지 | B48: =E12-B12 -> -2791735248 | C48: =B48/B12 -> -0.11301555
A49: 투자부동산_건물 | B49: =E13-B13 -> 1144541982 | C49: =B49/B13 -> 0.24281662 | E49: 투자부동산_건설중인자산에서 대체되어 증가
...

Sheet 4600_투자부동산_회계처리
G2: 조서No. 4620
A3: 투자부동산
A4: 투자부동산 회계처리
A7: 1 | B7: 분류원칙 | C7: 임대수익이나 시세차익을 얻기 위하여 보유하고 있는 부동산을 투자부동산으로 분류
A8: 2 | B8: 취득시 | C8: 취득시 발생한 거래원가를 포함하여 최초 인식시점에서 원가로 측정
A9: 3 | B9: 취득후 | C9: 취득원가에서 감감상각누계액과 손상차손누계액을 차감한 금액을 장부금액으로 표시
C10: 후속원가는 자산으로부터 발생하는 미래경제적효익이 유입될 가능성이 높으며 그 원가를
C11: 신뢰성 있게 측정할 수 있는 경우에 한하여 자산의 장부금액에 포함하거나 적절한 경우 별도
C12: 의 자산으로 이식
A13: 4 | B13: 건물 상각내용연수 | C13: 30년
A14: 5 | B14: 건물 상각방법 | C14: 정액법
A15: 6 | B15: 손상차손 환입
C16: 구분 | D16: 주요 내용
C17: 환입의 조건 | D17: • 과거에 인식한 손상차손의 감소/소멸 징후 검토 후, 징후가 있을 시 회수가능액 추정
D19: • 직전 손상차손 인식 이후 회수가능액 산정 추정치가 달라진 경우에만 환입 가능
D21: • 주의: 단순한 시간 경과에 따른 현재가치 증가만으로는 환입 불가
C22: 환입 한도 | D22: • 손상차손환입으로 증액되는 장부금액은 과거에 손상차손을 인식하지 않았을 경우의 장부금액(감가상각 후 잔액)을 초과할 수 없음
C23: 손익 인식 | D23: • 계산된 손상차손환입액은 즉시 당기손익으로 인식하여 장부금액을 증액함
C24: 후속 감가상각비 조정 | D24: • 환입 인식 후에는 **(수정된 장부금액 - 잔존가치)**를 남은 내용연수에 걸쳐 체계적으로 배분하도록 미래 기간의 감가상각비를 조정해야 함

Sheet 4600_투자부동산_매각예정자산대체
A2: 주식회사 경남제약 | G2: 조서No. 4630
A3: 투자부동산
A4: 투자부동산 매각예정자산대체
A7: 개요 | B7: 회사는 당반기 중 신당동소재 투자부동산을 관계횟인 아센디오에 매각계약을 체결함
A8: 계약체결일 | B8: 46210
A9: 양수기준일 | B9: 46244
A10: 등기예정일 | B10: 46245
A11: 매매금액 | B11: 13100369000
A12: 거래형태 | B12: 아센디오에 대한 현물출자
A13: 외부평가기관 | B13: 성운회계법인
A14: 외부평가기관의 의견 | B14: 적정
A15: 감정평가기관 | B15: 미래새한감정평가법인
A16: 소재지 | B16: 서울 중구 신당동 60-14,15,16
A17: 면젹 | B17: 토지: 461.7, 건물: 1,959.12
A18: 평가액
A19: 토지 | B19: 공시지가 기준일에 의한 토지단가(원/m2) | C19: 거래사례비교법에 의한 토지단가(원/m2) | D19: 결정단가(원/m2) | E19: 면적 | F19: 감정가액
B20: 17400000 | C20: 17900000 | D20: =B20 -> 17400000 | E20: 461.7 | F20: =D20*E20 -> 8033580000
A22: 건물 | B22: 층별 | C22: 공부면적 | D22: 사정면적 | E22: 적용단가 1) | F22: 감정가액
B23: 지3층 | C23: 95.49 | D23: =SUM(C23:C31) -> 1938.41 | E23: 2600000 | F23: =D23*E23 -> 5.039866e+09
B24: 지2층 | C24: 326.49
B25: 지1층 | C25: 333.98
B26: 1층 | C26: 203.96
B27: 2층 | C27: 226.99
B28: 3층 | C28: 218.37
B29: 4층 | C29: 209.24
B30: 5층 | C30: 183.74
B31: 6층 | C31: 140.15
B32: 옥탑1층 | C32: 20.71 | D32: 20.71 | E32: 1300000 | F32: =D32*E32 -> 26923000
B33: 합계 | F33: =SUM(F23:F32) -> 5.066789e+09
F34: =F33+F20=B11 -> TRUE
B35: 1) 적용단가는 재조달원가를 사용
A37: 매각예정자산대체분개> | B37: 투자부동산_건물감가상각누계액 | C37: 67022507 | D37: 투자부동산_토지 | E37: 7072519926
B38: 투자부동산_건물손상차손누계액 | C38: =-'4600_투자부동산'!E26 -> 0 | D38: 투자부동산_건물 | E38: 11147763220
B39: 매각예정자산 | C39: =B11 -> 13100369000
B40: 매갹예정자산 손상차손 | C40: =E37+E38-C37-C38-C39 -> 5052891639

Sheet 4600_투자부동산_증가
A2: =기본사항!C8 -> 주식회사 경남제약 | G2: 조서No. 4601
A3: 투자부동산
A4: 투자부동산 증감
A6: 투자부동산_토지증가>
A7: 전표일자 | B7: 전표번호 | C7: 부서 | D7: 사원명 | E7: 계정명 | F7: 차대구분 | G7: 차변 | H7: 대변 | I7: 적요 | J7: 승인요청일 | K7: 지급요청일 | L7: 반제일자 | M7: 거래처 | N7: 거래처명 | O7: 전표상태 | P7: 처리사유 | Q7: 등록일자 | R7: 회계번호 | S7: 승인자 | T7: 전표유형 | U7: 구분 | V7: PK | W7: 구분
A8: 46175 | B8: A0005 | C8: 재무팀 | D8: 서정아 | E8: 투자부동산_토지 | F8: 차변 | G8: 2140392339 | H8: 0 | I8: 225013 경남제약타워 9층 사용 용도 변경으로 인한 유형자산↔투자부동산 대체 | O8: 승인 | Q8: 46175 | R8: 20260602A0005 | T8: 경리전표 | U8: 당기 | V8: 000A0005 | W8: 대체
A9: 46175 | B9: A0006 | C9: 재무팀 | D9: 서정아 | E9: 투자부동산_토지 | F9: 차변 | G9: 2140392339 | H9: 0 | I9: 225013 경남제약타워 11층 사용 용도 변경으로 인한 유형자산↔투자부동산 대체 | O9: 승인 | Q9: 46175 | R9: 20260602A0006 | T9: 경리전표 | U9: 당기 | V9: 000A0006 | W9: 대체
G11: =SUM(G8:G10) -> 4280784678 | H11: =G11='4600_투자부동산'!C12 -> TRUE
A15: 투자부동산_건물증가>
A16: 전표일자 | B16: 전표번호 | C16: 부서 | D16: 사원명 | E16: 계정명 | F16: 차대구분 | G16: 차변 | H16: 대변 | I16: 적요 | J16: 승인요청일 | K16: 지급요청일 | L16: 반제일자 | M16: 거래처 | N16: 거래처명 | O16: 전표상태 | P16: 처리사유 | Q16: 등록일자 | R16: 회계번호 | S16: 승인자 | T16: 전표유형 | U16: 구분 | V16: PK | W16: 구분
A17: 46114 | B17: A0005 | C17: 재무팀 | D17: 서정아 | E17: 투자부동산_건물 | F17: 차변 | G17: 11147763220 | H17: 0 | I17: 225013 신당동 160-14,15,16 건물 | O17: 승인 | Q17: 46114 | R17: 20260402A0005 | T17: 경리전표 | U17: 당기 | V17: 000A0005 | W17: 대체
A18: 46175 | B18: A0005 | C18: 재무팀 | D18: 서정아 | E18: 투자부동산_건물 | F18: 차변 | G18: 572270991 | H18: 0 | I18: 225013 경남제약타워 9층 사용 용도 변경으로 인한 유형자산↔투자부동산 대체 | O18: 승인 | Q18: 46175 | R18: 20260602A0005 | T18: 경리전표 | U18: 당기 | V18: 000A0005 | W18: 대체
A19: 46175 | B19: A0006 | C19: 재무팀 | D19: 서정아 | E19: 투자부동산_건물 | F19: 차변 | G19: 572270991 | H19: 0 | I19: 225013 경남제약타워 11층 사용 용도 변경으로 인한 유형자산↔투자부동산 대체 | O19: 승인 | Q19: 46175 | R19: 20260602A0006 | T19: 경리전표 | U19: 당기 | V19: 000A0006 | W19: 대체
G21: =SUM(G17:G20) -> 12292305202 | H21: =G21='4600_투자부동산'!C13 -> TRUE
A24: 투자부동산_건설중인자산 증가>
A25: 전표일자 | B25: 전표번호 | C25: 부서 | D25: 사원명 | E25: 계정명 | F25: 차대구분 | G25: 차변 | H25: 대변 | I25: 적요 | J25: 승인요청일 | K25: 지급요청일 | L25: 반제일자 | M25: 거래처 | N25: 거래처명 | O25: 전표상태 | P25: 처리사유 | Q25: 등록일자 | R25: 회계번호 | S25: 승인자 | T25: 전표유형 | U25: 구분 | V25: PK | W25: 구분
A26: 46028 | B26: R0005 | C26: 인사팀 | D26: 김우진 | E26: 투자부동산_건설중인자산 | F26: 차변 | G26: 2000000 | H26: 0 | I26: 225013 신당동 160-14외2필지 사용승인 서류 중 건축물관리계획서 작성 업체 지급 건 / 202601-인사팀-13 | J26: 2026-01-06 | M26: R07530 | N26: 주식회사 건물닥터 | O26: 승인 | Q26: 46028 | R26: 20260106R0002 | S26: 김규리 | T26: 결의전표 | U26: 당기 | V26: 000R0005 | W26: 취득
A27: 46028 | B27: R0006 | C27: 인사팀 | D27: 김우진 | E27: 투자부동산_건설중인자산 | F27: 차변 | G27: 11500000 | H27: 0 | I27: 225013 투자 부동산 신당동 소방전기통신 감리 필증 완료 잔급 지급 건 / 202601-인사팀-30 | J27: 2026-01-06 | M27: R07121 | N27: 주식회사 신화에이앤씨(구.신화제이비) | O27: 승인 | Q27: 46028 | R27: 20260106R0005 | S27: 박재윤 | T27: 결의전표 | U27: 당기 | V27: 000R0006 | W27: 취득
A28: 46034 | B28: R0003 | C28: 인사팀 | D28: 김우진 | E28: 투자부동산_건설중인자산 | F28: 차변 | G28: 15000000 | H28: 0 | I28: 225013 투자 부동산 신당동 엠엔지종합건설 12차36회 나은티에스아이 기성금 직불 건 / 202601-인사팀-36 | J28: 2026-01-12 | M28: R06988 | N28: (주)나은티에스아이 | O28: 승인 | Q28: 46034 | R28: 20260112R0002 | S28: 김규리 | T28: 결의전표 | U28: 당기 | V28: 000R0003 | W28: 취득
A29: 46035 | B29: R0008 | C29: 인사팀 | D29: 김우진 | E29: 투자부동산_건설중인자산 | F29: 차변 | G29: 15970000 | H29: 0 | I29: 225013 투자 부동산 신당동 엠엔지종합건설 12차37회 범한 기성금 직불 건 / 202601-인사팀-57 | J29: 2026-01-13 | M29: R07416 | N29: 범한 | O29: 승인 | Q29: 46035 | R29: 20260113R0005 | S29: 김규리 | T29: 결의전표 | U29: 당기 | V29: 000R0008 | W29: 취득
A30: 46036 | B30: R0003 | C30: 인사팀 | D30: 김우진 | E30: 투자부동산_건설중인자산 | F30: 차변 | G30: 18540140 | H30: 0 | I30: 225013 투자부동산 신당동(160-14 외2필지) 하수도원인자부담금 지급 건/ 202601-인사팀- | J30: 2026-01-14 | M30: R06961 | N30: 서울시중구청 | O30: 승인 | Q30: 46036 | R30: 20260114R0001 | S30: 박재윤 | T30: 결의전표 | U30: 당기 | V30: 000R0003 | W30: 취득
A31: 46040 | B31: R0001 | C31: 인사팀 | D31: 김우진 | E31: 투자부동산_건설중인자산 | F31: 차변 | G31: 1614228 | H31: 0 | I31: 225013 신당동 160-14,15,16 12월 전기 요금 / 202508-인사팀-40 | J31: 2026-01-18 | M31: R01229 | N31: 한국전력공사(통합) | O31: 승인 | Q31: 46040 | R31: 20260118R0001 | S31: 박재윤 | T31: 결의전표 | U31: 당기 | V31: 000R0001 | W31: 취득
A32: 46040 | B32: R0001 | C32: 인사팀 | D32: 김우진 | E32: 투자부동산_건설중인자산 | F32: 차변 | G32: 43580 | H32: 0 | I32: 225013 전력기금 | J32: 2026-01-18 | M32: R01229 | N32: 한국전력공사(통합) | O32: 승인 | Q32: 46040 | R32: 20260118R0001 | S32: 박재윤 | T32: 결의전표 | U32: 당기 | V32: 000R0001 | W32: 취득
A33: 46042 | B33: R0006 | C33: 인사팀 | D33: 김우진 | E33: 투자부동산_건설중인자산 | F33: 차변 | G33: 120000 | H33: 0 | I33: 225013 신당동 160-14외2필지 전기안전관리자 수수료 01월 비용 / 202507-인사팀-84 | J33: 2026-01-20 | M33: R07417 | N33: 극동파워테크 | O33: 승인 | Q33: 46042 | R33: 20260120R0002 | S33: 김규리 | T33: 결의전표 | U33: 당기 | V33: 000R0006 | W33: 취득
A34: 46042 | B34: R0012 | C34: 인사팀 | D34: 김우진 | E34: 투자부동산_건설중인자산 | F34: 차변 | G34: 150000 | H34: 0 | I34: 225013 신당동 160-14외2필지 승강기 유지관리 01월 비용 / 202512-인사팀-65 | J34: 2026-01-20 | M34: R07538 | N34: 현대엘리베이터(주) 강북지사 | O34: 승인 | Q34: 46042 | R34: 20260120R0005 | S34: 김규리 | T34: 결의전표 | U34: 당기 | V34: 000R0012 | W34: 취득
A35: 46053 | B35: A0015 | C35: 재무팀 | D35: 서정아 | E35: 투자부동산_건설중인자산 | F35: 차변 | G35: 4813150 | H35: 0 | I35: 225013 2026.01 이자비용 (신한40억) 차입원가 자본화 계정 대체 | M35: P00190 | N35: 신한은행 압구정역기업금융 | O35: 승인 | Q35: 46053 | R35: 20260131A0015 | T35: 경리전표 | U35: 당기 | V35: 000A0015 | W35: 취득
A36: 46053 | B36: A0015 | C36: 재무팀 | D36: 서정아 | E36: 투자부동산_건설중인자산 | F36: 차변 | G36: 7620822 | H36: 0 | I36: 225013 2026.01 이자비용 (신한40억) 차입원가 자본화 계정 대체 | M36: P00190 | N36: 신한은행 압구정역기업금융 | O36: 승인 | Q36: 46053 | R36: 20260131A0015 | T36: 경리전표 | U36: 당기 | V36: 000A0015 | W36: 취득
A37: 46063 | B37: R0002 | C37: 인사팀 | D37: 김우진 | E37: 투자부동산_건설중인자산 | F37: 차변 | G37: 90890 | H37: 0 | I37: 225013 신당동 160-14,15,16 수도 요금 11.23 ~ 01.22 / 202510-인사팀-32 | J37: 2026-02-10 | M37: R07350 | N37: 중부수도사업소 | O37: 승인 | Q37: 46063 | R37: 20260210R0002 | S37: 김규리 | T37: 결의전표 | U37: 당기 | V37: 000R0002 | W37: 취득
A38: 46063 | B38: R0004 | C38: 인사팀 | D38: 김우진 | E38: 투자부동산_건설중인자산 | F38: 차변 | G38: 11300000 | H38: 0 | I38: 225013 투자 부동산 신당동 엠엔지종합건설 12차38회 단우건설 기성금 직불 건 / 202601-인사팀-57 | J38: 2026-02-10 | M38: R07326 | N38: 단우건설(주) | O38: 승인 | Q38: 46063 | R38: 20260210R0004 | S38: 김규리 | T38: 결의전표 | U38: 당기 | V38: 000R0004 | W38: 취득
A39: 46063 | B39: R0004 | C39: 인사팀 | D39: 김우진 | E39: 투자부동산_건설중인자산 | F39: 차변 | G39: 9454545 | H39: 0 | I39: 225013 투자 부동산 신당동 엠엔지종합건설 12차38회 유현이앤지 기성금 직불 건 / 202601-인사팀-57 | J39: 2026-02-10 | M39: R07486 | N39: 유현이앤지 주식회사 | O39: 승인 | Q39: 46063 | R39: 20260210R0004 | S39: 김규리 | T39: 결의전표 | U39: 당기 | V39: 000R0004 | W39: 취득
A40: 46064 | B40: R0003 | C40: 인사팀 | D40: 김우진 | E40: 투자부동산_건설중인자산 | F40: 차변 | G40: 15000000 | H40: 0 | I40: 225013 투자 부동산 신당동 엠엔지종합건설 12차39회 범한 기성금 직불 건 / 202602-인사팀-34 | J40: 2026-02-11 | M40: R07416 | N40: 범한 | O40: 승인 | Q40: 46064 | R40: 20260211R0002 | S40: 김규리 | T40: 결의전표 | U40: 당기 | V40: 000R0003 | W40: 취득
A41: 46071 | B41: R0001 | C41: 인사팀 | D41: 김우진 | E41: 투자부동산_건설중인자산 | F41: 차변 | G41: 35500 | H41: 0 | I41: 225013 전력기금 | J41: 2026-02-18 | M41: R01229 | N41: 한국전력공사(통합) | O41: 승인 | Q41: 46071 | R41: 20260218R0001 | S41: 김규리 | T41: 결의전표 | U41: 당기 | V41: 000R0001 | W41: 취득
A42: 46071 | B42: R0001 | C42: 인사팀 | D42: 김우진 | E42: 투자부동산_건설중인자산 | F42: 차변 | G42: 1314880 | H42: 0 | I42: 225013 신당동 160-14,15,16 2월 전기 요금 / 202508-인사팀-40 | J42: 2026-02-18 | M42: R01229 | N42: 한국전력공사(통합) | O42: 승인 | Q42: 46071 | R42: 20260218R0001 | S42: 김규리 | T42: 결의전표 | U42: 당기 | V42: 000R0001 | W42: 취득
A43: 46073 | B43: R0004 | C43: 인사팀 | D43: 김우진 | E43: 투자부동산_건설중인자산 | F43: 차변 | G43: 120000 | H43: 0 | I43: 225013 신당동 160-14외2필지 전기안전관리자 수수료 02월 비용 / 202507-인사팀-84 | J43: 2026-02-20 | M43: R07417 | N43: 극동파워테크 | O43: 승인 | Q43: 46073 | R43: 20260220R0003 | S43: 김규리 | T43: 결의전표 | U43: 당기 | V43: 000R0004 | W43: 취득
A44: 46073 | B44: R0005 | C44: 인사팀 | D44: 김우진 | E44: 투자부동산_건설중인자산 | F44: 차변 | G44: 150000 | H44: 0 | I44: 225013 신당동 160-14외2필지 승강기 유지관리 02월 비용 / 202512-인사팀-65 | J44: 2026-02-20 | M44: R07538 | N44: 현대엘리베이터(주) 강북지사 | O44: 승인 | Q44: 46073 | R44: 20260220R0002 | S44: 김규리 | T44: 결의전표 | U44: 당기 | V44: 000R0005 | W44: 취득
A45: 46077 | B45: R0016 | C45: 인사팀 | D45: 김우진 | E45: 투자부동산_건설중인자산 | F45: 차변 | G45: 5440000 | H45: 0 | I45: 225013 투자 부동산 신당동 엠엔지종합건설 12차40회 은혜종합건축 기성금 직불 건 / 202603-인사팀-4 | J45: 2026-02-24 | M45: R07433 | N45: 은혜종합건축 | O45: 승인 | Q45: 46077 | R45: 20260224R0003 | S45: 김규리 | T45: 결의전표 | U45: 당기 | V45: 000R0016 | W45: 취득
A46: 46077 | B46: R0016 | C46: 인사팀 | D46: 김우진 | E46: 투자부동산_건설중인자산 | F46: 차변 | G46: 4000000 | H46: 0 | I46: 225013 투자 부동산 신당동 엠엔지종합건설 12차40회 주당공사 기성금 직불 건 / 202603-인사팀-4 | J46: 2026-02-24 | M46: R07403 | N46: 주당공사 | O46: 승인 | Q46: 46077 | R46: 20260224R0003 | S46: 김규리 | T46: 결의전표 | U46: 당기 | V46: 000R0016 | W46: 취득
A47: 46077 | B47: R0016 | C47: 인사팀 | D47: 김우진 | E47: 투자부동산_건설중인자산 | F47: 차변 | G47: 1970000 | H47: 0 | I47: 225013 투자 부동산 신당동 엠엔지종합건설 12차40회 화니건설 기성금 직불 건 / 202603-인사팀-4 | J47: 2026-02-24 | M47: R07478 | N47: 화니건설(주) | O47: 승인 | Q47: 46077 | R47: 20260224R0003 | S47: 김규리 | T47: 결의전표 | U47: 당기 | V47: 000R0016 | W47: 취득
A48: 46081 | B48: A0010 | C48: 재무팀 | D48: 서정아 | E48: 투자부동산_건설중인자산 | F48: 차변 | G48: 4813150 | H48: 0 | I48: 225013 2026.02 이자비용 (신한40억) 차입원가 자본화 계정 대체 | M48: P00190 | N48: 신한은행 압구정역기업금융 | O48: 승인 | Q48: 46081 | R48: 20260228A0010 | T48: 경리전표 | U48: 당기 | V48: 000A0010 | W48: 취득
A49: 46081 | B49: A0010 | C49: 재무팀 | D49: 서정아 | E49: 투자부동산_건설중인자산 | F49: 차변 | G49: 6417534 | H49: 0 | I49: 225013 2026.02 이자비용 (신한40억) 차입원가 자본화 계정 대체 | M49: P00190 | N49: 신한은행 압구정역기업금융 | O49: 승인 | Q49: 46081 | R49: 20260228A0010 | T49: 경리전표 | U49: 당기 | V49: 000A0010 | W49: 취득
...

Sheet 4600_투자부동산_감소
A2: =기본사항!C8 -> 주식회사 경남제약 | G2: 조서No. 4601
A3: 투자부동산
A4: 투자부동산 감소
A6: 투자부동산_토지감소>
A7: 전표일자 | B7: 전표번호 | C7: 부서 | D7: 사원명 | E7: 계정명 | F7: 차대구분 | G7: 차변 | H7: 대변 | I7: 적요 | J7: 승인요청일 | K7: 지급요청일 | L7: 반제일자 | M7: 거래처 | N7: 거래처명 | O7: 전표상태 | P7: 처리사유 | Q7: 등록일자 | R7: 회계번호 | S7: 승인자 | T7: 전표유형 | U7: 구분 | V7: PK | W7: 구분
A8: 46023 | B8: A0006 | C8: 재무팀 | D8: 서정아 | E8: 투자부동산_토지 | F8: 대변 | G8: 0 | H8: 545209561 | I8: 225013 강남구 언주로 702(B2층-전기실) 유형자산대체 | O8: 승인 | Q8: 46023 | R8: 20260101A0006 | T8: 경리전표 | U8: 당기 | V8: 000A0006 | W8: 대체
A9: 46023 | B9: A0006 | C9: 재무팀 | D9: 서정아 | E9: 투자부동산_토지 | F9: 대변 | G9: 0 | H9: 594368641 | I9: 225013 강남구 언주로 702(B3층-기계실) 유형자산대체 | O9: 승인 | Q9: 46023 | R9: 20260101A0006 | T9: 경리전표 | U9: 당기 | V9: 000A0006 | W9: 대체
A10: 46113 | B10: A0023 | C10: 재무팀 | D10: 서정아 | E10: 투자부동산_토지 | F10: 대변 | G10: 0 | H10: -545209561 | I10: 225013 강남구 언주로 702(B2층-전기실) 유형자산대체 | O10: 승인 | Q10: 46113 | R10: 20260401A0023 | T10: 경리전표 | U10: 당기 | V10: 000A0023 | W10: 대체
A11: 46113 | B11: A0023 | C11: 재무팀 | D11: 서정아 | E11: 투자부동산_토지 | F11: 대변 | G11: 0 | H11: -594368641 | I11: 225013 강남구 언주로 702(B3층-기계실) 유형자산대체 | O11: 승인 | Q11: 46113 | R11: 20260401A0023 | T11: 경리전표 | U11: 당기 | V11: 000A0023 | W11: 대체
E12: 투자부동산_토지 | F12: 대변 | H12: ='4600_투자부동산_매각예정자산대체'!E37 -> 7072519926 | I12: 매각예정자산대체
H13: =SUM(H8:H12) -> 7072519926 | I13: =H13='4600_투자부동산'!D12 -> TRUE
A15: 투자부동산_건물감소>
A16: 전표일자 | B16: 전표번호 | C16: 부서 | D16: 사원명 | E16: 계정명 | F16: 차대구분 | G16: 차변 | H16: 대변 | I16: 적요 | J16: 승인요청일 | K16: 지급요청일 | L16: 반제일자 | M16: 거래처 | N16: 거래처명 | O16: 전표상태 | P16: 처리사유 | Q16: 등록일자 | R16: 회계번호 | S16: 승인자 | T16: 전표유형 | U16: 구분 | V16: PK | W16: 구분
A17: 46023 | B17: A0006 | C17: 재무팀 | D17: 서정아 | E17: 투자부동산_건물 | F17: 대변 | G17: 0 | H17: 145771227 | I17: 225013 강남구 언주로 702(B2층-전기실) 유형자산대체 | O17: 승인 | Q17: 46023 | R17: 20260101A0006 | T17: 경리전표 | U17: 당기 | V17: 000A0006 | W17: 대체
A18: 46023 | B18: A0006 | C18: 재무팀 | D18: 서정아 | E18: 투자부동산_건물 | F18: 대변 | G18: 0 | H18: 158914758 | I18: 225013 강남구 언주로 702(B3층-기계실) 유형자산대체 | O18: 승인 | Q18: 46023 | R18: 20260101A0006 | T18: 경리전표 | U18: 당기 | V18: 000A0006 | W18: 대체
A19: 46113 | B19: A0023 | C19: 재무팀 | D19: 서정아 | E19: 투자부동산_건물 | F19: 대변 | G19: 0 | H19: -145771227 | I19: 225013 강남구 언주로 702(B2층-전기실) 유형자산대체 | O19: 승인 | Q19: 46113 | R19: 20260401A0023 | T19: 경리전표 | U19: 당기 | V19: 000A0023 | W19: 대체
A20: 46113 | B20: A0023 | C20: 재무팀 | D20: 서정아 | E20: 투자부동산_건물 | F20: 대변 | G20: 0 | H20: -158914758 | I20: 225013 강남구 언주로 702(B3층-기계실) 유형자산대체 | O20: 승인 | Q20: 46113 | R20: 20260401A0023 | T20: 경리전표 | U20: 당기 | V20: 000A0023 | W20: 대체
E21: 투자부동산_건물 | F21: 대변 | G21: 1 | H21: ='4600_투자부동산_매각예정자산대체'!E38 -> 11147763220 | I21: 매각예정자산대체
H22: =SUM(H17:H21) -> 11147763220 | I22: =H22-'4600_투자부동산'!D13 -> 0
A24: 투자부동산_건설중인자산 감소>
A25: 전표일자 | B25: 전표번호 | C25: 부서 | D25: 사원명 | E25: 계정명 | F25: 차대구분 | G25: 차변 | H25: 대변 | I25: 적요 | J25: 승인요청일 | K25: 지급요청일 | L25: 반제일자 | M25: 거래처 | N25: 거래처명 | O25: 전표상태 | P25: 처리사유 | Q25: 등록일자 | R25: 회계번호 | S25: 승인자 | T25: 전표유형 | U25: 구분 | V25: PK | W25: 구분
A26: 46114 | B26: A0005 | C26: 재무팀 | D26: 서정아 | E26: 투자부동산_건설중인자산 | F26: 대변 | G26: 0 | H26: 11147763220 | I26: 225013 신당동 160-14,15,16 건물 건설중인자산->건물 대체 | O26: 승인 | Q26: 46114 | R26: 20260402A0005 | T26: 경리전표 | U26: 당기 | V26: 000A0005 | W26: 대체
H29: =SUM(H26:H28) -> 11147763220

Sheet 4600_투자부동산명세
A2: =기본사항!C8 -> 주식회사 경남제약 | G2: 조서No. 4610
A3: 투자부동산
A4: 투자부동산 분석적 검토
A7: 자산분류 | B7: 사업장 | C7: 부문 | D7: 자산코드 | E7: 자산명 | F7: 기초자산가액 | G7: 자산대체증가 | H7: 자산대체감소 | I7: 기말자산가액 | J7: 감가상각누계액 | K7: 임대인 | L7: 임대보증금 | M7: 임대차계약서
A8: 투자(건물) | B8: 서울 | C8: 판관 | D8: IB_0002 | E8: 강남구 언주로 702(1층) | F8: 424354484 | G8: 0 | H8: 0 | I8: 424354484 | J8: 77798317 | K8: 주식회사 바나플에프엔비 | L8: 160000000
A9: 투자(건물) | B9: 서울 | C9: 판관 | D9: IB_0003 | E9: 강남구 언주로 702(2층) | F9: 586944607 | G9: 0 | H9: 0 | I9: 586944607 | J9: 107606506 | K9: 공실
A10: 투자(건물) | B10: 서울 | C10: 판관 | D10: IB_0004 | E10: 강남구 언주로 702(3층) | F10: 586944607 | G10: 0 | H10: 0 | I10: 586944607 | J10: 107606506 | K10: 스테이영피부과의원 | L10: 120000000
A11: 투자(건물) | B11: 서울 | C11: 판관 | D11: IB_0005 | E11: 강남구 언주로 702(4층) | F11: 521592712 | G11: 0 | H11: 0 | I11: 521592712 | J11: 95625323 | K11: 공실
A12: 투자(건물) | B12: 서울 | C12: 판관 | D12: IB_0006 | E12: 강남구 언주로 702(5층) | F12: 572270991 | G12: 0 | H12: 0 | I12: 572270991 | J12: 104916341 | K12: 일부임대
A13: 투자(건물) | B13: 서울 | C13: 판관 | D13: IB_0007 | E13: 강남구 언주로 702(9층) | G13: 572270991 | H13: 0 | I13: 572270991 | J13: 104916341 | K13: ㈜미니쉬테크놀로지 주식회사 | L13: 120000000
A14: 투자(건물) | B14: 서울 | C14: 판관 | D14: IB_0008 | E14: 강남구 언주로 702(10층) | F14: 572270991 | G14: 0 | H14: 0 | I14: 572270991 | J14: 104916341 | K14: ㈜미니쉬테크놀로지 주식회사 | L14: 120000000
A15: 투자(건물) | B15: 서울 | C15: 판관 | D15: B_0022 | E15: 서울특별시 강남구 언주로 702(11층) | G15: 572270991 | H15: 0 | I15: 572270991 | J15: 104916341 | K15: ㈜미니쉬테크놀로지 주식회사 | L15: 120000000
A16: 투자(건물) | B16: 서울 | C16: 판관 | D16: IB_0009 | E16: 강남구 언주로 702(12층) | F16: 572270991 | G16: 0 | H16: 0 | I16: 572270991 | J16: 104916341 | K16: (주)엘엑스인베스트먼트 | L16: 100000000
A17: 투자(건물) | B17: 서울 | C17: 판관 | D17: IB_0010 | E17: 강남구 언주로 702(13층) | F17: 572270991 | G17: 0 | H17: 0 | I17: 572270991 | J17: 104916341 | K17: ㈜미니쉬테크놀로지 주식회사 | L17: 120000000
A18: 투자(건물) | B18: 서울 | C18: 판관 | D18: IB_0011 | E18: 강남구 언주로 702(B3층-기계실) | F18: 158914758 | G18: 0 | H18: 0 | I18: 158914758 | J18: 29134364
A19: 투자(건물) | B19: 서울 | C19: 판관 | D19: IB_0012 | E19: 강남구 언주로 702(B2층-전기실) | F19: 145771227 | G19: 0 | H19: 0 | I19: 145771227 | J19: 26724720
A20: 투자(건물) | B20: 서울 | C20: 판관 | D20: IB_0032 | E20: 신당동 160-14,15,16 건물 | F20: 0 | G20: 11147763220 | H20: 0 | I20: 11147763220 | J20: 0
E21: 합계 | F21: =SUM(F8:F20) -> 4713606359 | G21: =SUM(G8:G20) -> 12292305202 | H21: =SUM(H8:H20) -> 0 | I21: =SUM(I8:I20) -> 17005911561 | J21: =SUM(J8:J20) -> 1073993782
F22: TRUE | I22: =I21='4600_투자부동산'!E13 -> FALSE
A24: 자산분류 | B24: 사업장 | C24: 부문 | D24: 자산코드 | E24: 자산명 | F24: 기초자산가액 | G24: 자산대체증가 | H24: 자산대체감소 | I24: 기말자산가액 | J24: 임대차계약서
A25: 투자(토지) | B25: 서울 | C25: 판관 | D25: IL_0002 | E25: 강남구 언주로 702(1층) | F25: 1587159058 | G25: 0 | H25: 0 | I25: 1587159058
A26: 투자(토지) | B26: 서울 | C26: 판관 | D26: IL_0003 | E26: 강남구 언주로 702(2층) | F26: 2195274194 | G26: 0 | H26: 0 | I26: 2195274194
A27: 투자(토지) | B27: 서울 | C27: 판관 | D27: IL_0004 | E27: 강남구 언주로 702(3층) | F27: 2195274194 | G27: 0 | H27: 0 | I27: 2195274194
A28: 투자(토지) | B28: 서울 | C28: 판관 | D28: IL_0005 | E28: 강남구 언주로 702(4층) | F28: 1950846823 | G28: 0 | H28: 0 | I28: 1950846823
A29: 투자(토지) | B29: 서울 | C29: 판관 | D29: IL_0006 | E29: 강남구 언주로 702(5층) | F29: 2140392339 | G29: 0 | H29: 0 | I29: 2140392339
A30: 투자(토지) | B30: 서울 | C30: 판관 | D30: IL_0007 | E30: 강남구 언주로 702(9층) | G30: 2140392339 | H30: 0 | I30: 2140392339
A31: 투자(토지) | B31: 서울 | C31: 판관 | D31: IL_0008 | E31: 강남구 언주로 702(10층) | F31: 2140392339 | G31: 0 | H31: 0 | I31: 2140392339
A32: 투자(토지) | B32: 서울 | C32: 판관 | D32: L_0010 | E32: 서울특별시 강남구 언주로 702(11층) | G32: 2140392339 | H32: 0 | I32: 2140392339
A33: 투자(토지) | B33: 서울 | C33: 판관 | D33: IL_0009 | E33: 강남구 언주로 702(12층) | F33: 2140392339 | G33: 0 | H33: 0 | I33: 2140392339
A34: 투자(토지) | B34: 서울 | C34: 판관 | D34: IL_0010 | E34: 강남구 언주로 702(13층) | F34: 2140392339 | G34: 0 | H34: 0 | I34: 2140392339
A35: 투자(토지) | B35: 서울 | C35: 판관 | D35: IL_0011 | E35: 강남구 언주로 702(B3층-기계실) | F35: 594368641 | G35: 0 | H35: 0 | I35: 594368641
A36: 투자(토지) | B36: 서울 | C36: 판관 | D36: IL_0012 | E36: 강남구 언주로 702(B2층-전기실) | F36: 545209561 | G36: 0 | H36: 0 | I36: 545209561
A37: 투자(토지) | B37: 서울 | C37: 판관 | D37: IL_0015 | E37: 신당동 160-14, 160-15, 160-16 | F37: 7072519926 | G37: 0 | H37: 0 | I37: 7072519926
E38: 합계 | F38: =SUM(F25:F37) -> 24702221753 | G38: =SUM(G25:G37) -> 4280784678 | H38: =SUM(H25:H37) -> 0 | I38: =SUM(I25:I37) -> 28983006431
F39: =F38='4600_투자부동산'!B12 -> TRUE | I39: =I38='4600_투자부동산'!E12 -> FALSE

Sheet 4600_투자부동산_감가상각비
A1: 신당동 감가상각비 조정
A2: 사업단위 : 경남제약 주식회사 | AT2: 단위 : 원
A3: No. | B3: 구분 | C3: 사업장 | D3: 경 비 부 문 | E3: 자산 코드 | F3: 자 산 명 | G3: 단위 | H3: 수량 | I3: 취득일 | J3: 내용 연수 | K3: 취 득 가 액 | Y3: 증가 및 대체가액 | Z3: 처분가액 | AA3: 합 계 | AB3: 감 가 상 각 누 계 액 | AR3: 손상누계 | AS3: 합 계 | AT3: 잔존가액
K4: 기초가액 | L4: 당기 취득액 | X4: 소 계 | AB4: 전 기 누계액 | AC4: 당기 감가상각액 | AO4: 소 계 | AP4: 대체가액 | AQ4: 처분가액 | AV4: IFRS기준 검증
L5: 01월 | M5: 02월 | N5: 03월 | O5: 04월 | P5: 05월 | Q5: 06월 | R5: 07월 | S5: 08월 | T5: 09월 | U5: 10월 | V5: 11월 | W5: 12월 | AC5: 01월 | AD5: 02월 | AE5: 03월 | AF5: 04월 | AG5: 05월 | AH5: 06월 | AI5: 07월 | AJ5: 08월 | AK5: 09월 | AL5: 10월 | AM5: 11월 | AN5: 12월 | AU5: 단순상각 | AV5: 월상각액 | AW5: ERP | AX5: 차이
A6: IB_0032 | B6: 투자부동산(건물) | C6: 부동산 | D6: 임대 | F6: 신당동 160-14,15,16 건물 | G6: ㎡ | I6: 46114 | J6: 30 | X6: =+SUM(L6:W6) -> 0 | Y6: 11147763220 | AA6: =+K6+X6+Y6-Z6 -> 11147763220 | AF6: 30966008 | AG6: 30966009 | AH6: 30966009 | AO6: =+SUM(AC6:AN6) -> 92898026 | AP6: 0 | AR6: 3105062380 | AS6: =AO6+AR6 -> 3197960406 | AT6: =+AA6-AS6 -> 7949802814 | AU6: =ROUNDDOWN(AA6/(J6*12),0) -> 30966008 | AV6: =+IF(AT6<=1000,0,ROUNDDOWN($AA6/($J6*12),0)) -> 30966008 | AW6: =AO6 -> 92898026 | AX6: =+AO6-AW6 -> 0
A7: 계 | K7: =+SUM(K6:W6) -> 0 | L7: =+SUM(#REF!) -> #REF! | M7: =+SUM(#REF!) -> #REF! | N7: =+SUM(#REF!) -> #REF! | O7: =+SUM(#REF!) -> #REF! | P7: =+SUM(#REF!) -> #REF! | Q7: =+SUM(#REF!) -> #REF! | R7: =+SUM(#REF!) -> #REF! | S7: =+SUM(#REF!) -> #REF! | ... W7: =+SUM(#REF!) -> #REF! | X7: =X6 -> 0 | Y7: =SUM(Y6:Y6) -> 11147763220 | AA7: =+SUM(AA6:AA6) -> 11147763220 | AB7: =SUM(AB6:AB6) -> 0 | AC7: =+SUM(AC6:AC6) -> 0 | AD7: =+SUM(AD6:AD6) -> 0 | AE7: =+SUM(AE6:AE6) -> 0 | AF7: =+SUM(AF6:AF6) -> 30966008 | AG7: =+SUM(AG6:AG6) -> 30966009 | AH7: =+SUM(AH6:AH6) -> 30966009 | AQ7: =+SUM(AQ6:AQ6) -> 0 | AR7: =+SUM(AR6:AR6) -> 3105062380 | AS7: =+SUM(AS6:AS6) -> 3197960406 | AT7: =+SUM(AT6:AT6) -> 7949802814
A9: 투자부동산 조정기표_ 손상 후 잔액
A10: No. | B10: 구분 | C10: 사업장 | D10: 경 비 부 문 | E10: 자산 코드 | F10: 자 산 명 | G10: 단위 | H10: 수량 | I10: 취득일 | J10: 내용 연수 | K10: 취 득 가 액 | Y10: 증가 및 대체가액 | Z10: 처분가액 | AA10: 합 계 | AB10: 감 가 상 각 누 계 액 | AR10: 손상누계 | AS10: 합 계 | AT10: 잔존가액
K11: 기초가액 | L11: 당기 취득액 | X11: 소 계 | AB11: 전 기 누계액 | AC11: 당기 감가상각액 | AO11: 소 계 | AP11: 대체가액 | AQ11: 처분가액 | AV11: IFRS기준 검증
L12: 01월 | M12: 02월 | N12: 03월 | O12: 04월 | P12: 05월 | Q12: 06월 | R12: 07월 | S12: 08월 | T12: 09월 | U12: 10월 | V12: 11월 | W12: 12월 | AC12: 01월 | AD12: 02월 | AE12: 03월 | AF12: 04월 | AG12: 05월 | AH12: 06월 | AI12: 07월 | AJ12: 08월 | AK12: 09월 | AL12: 10월 | AM12: 11월 | AN12: 12월 | AU12: 단순상각 | AV12: 월상각액 | AW12: ERP | AX12: 차이
A13: IB_0032 | B13: 투자부동산(건물) | C13: 부동산 | D13: 임대 | F13: 신당동 160-14,15,16 건물 | G13: ㎡ | I13: 46114 | J13: 30 | X13: 0 | Y13: =Y6-AR6 -> 8042700840 | AA13: 8042700840 | AF13: =AA13/30/12 -> 22340836 | AG13: 22340836 | AH13: 22340836 | AO13: =SUM(AF13:AH13) -> 67022507 | AP13: 0 | AR13: 3105062380 | AT13: =AA13-AO13 -> 7975678333 | AU13: 30966008 | AV13: 30966008 | AW13: 92898026 | AX13: 0
A14: 차액 | AF14: =AF6-AF13 -> 8625172.3 | AG14: =AG6-AG13 -> 8625173.3 | AH14: =AH6-AH13 -> 8625173.3 | AO14: =SUM(AF14:AH14) -> 25875519
A15: 계 | L15: 0 | M15: 0 | N15: 0 | O15: 0 | P15: 0 | Q15: 0 | R15: 0 | S15: 0 | T15: 0 | U15: 0 | V15: 0 | W15: 0 | X15: 0 | Y15: =Y13 -> 8042700840 | Z15: 0 | AA15: =AA13 -> 8042700840 | AI15: 0 | AJ15: 0 | AK15: 0 | AL15: 0 | AM15: 0 | AN15: 0 | AO15: =AO13 -> 67022507 | AP15: =AP13 -> 0 | AQ15: =AQ13 -> 0 | AR15: =AR13 -> 3105062380 | AS15: =AS13 -> 0 | AT15: =AT13 -> 7975678333
AD16: (차) | AE16: 감가상각비(판관) | AF16: =-SUM(AF14:AH14) -> -25875519 | AG16: (대) | AH16: 투자부동산 감가상각누계액 | AI16: =AF16 -> -25875519
A19: 아산 | B19: =SUMIF($C:$C,$A19,Z:Z) -> 0 | D19: : 매각 | F19: 아산 | G19: =SUMIF($C:$C,$F19,AQ:AQ) -> 0 | I19: : 누계차감
A20: 의령 | B20: =SUMIF($C:$C,$A20,Z:Z) -> 0 | D20: : 매각 | F20: 1 | G20: =SUMIF($C:$C,$F20,AQ:AQ) -> 0 | I20: : 누계차감
A21: 계 | B21: =SUM(B19:C20) -> 0 | D21: =B21=Z7 -> TRUE | F21: 계 | G21: =SUM(G19:H20) -> 0 | I21: =G21=AQ7 -> TRUE
A23: 집계표 data | I23: 서울 | J23: 판관 | L23: =+SUMIFS(L:L,$C:$C,$I23,$D:$D,$J23) -> 0 | M23: =+SUMIFS(M:M,$C:$C,$I23,$D:$D,$J23) -> 0 | N23: =+SUMIFS(N:N,$C:$C,$I23,$D:$D,$J23) -> 0 | O23: =+SUMIFS(O:O,$C:$C,$I23,$D:$D,$J23) -> 0 | P23: =+SUMIFS(P:P,$C:$C,$I23,$D:$D,$J23) -> 0 | Q23: =+SUMIFS(Q:Q,$C:$C,$I23,$D:$D,$J23) -> 0 | R23: =+SUMIFS(R:R,$C:$C,$I23,$D:$D,$J23) -> 0 | S23: =+SUMIFS(S:S,$C:$C,$I23,$D:$D,$J23) -> 0 | T23: =+SUMIFS(T:T,$C:$C,$I23,$D:$D,$J23) -> 0 | U23: =+SUMIFS(U:U,$C:$C,$I23,$D:$D,$J23) -> 0 | V23: =+SUMIFS(V:V,$C:$C,$I23,$D:$D,$J23) -> 0 | W23: =+SUMIFS(W:W,$C:$C,$I23,$D:$D,$J23) -> 0 | AC23: =+SUMIFS(AC:AC,$C:$C,$I23,$D:$D,$J23) -> 0 | AD23: =+SUMIFS(AD:AD,$C:$C,$I23,$D:$D,$J23) -> 0 | AE23: =+SUMIFS(AE:AE,$C:$C,$I23,$D:$D,$J23) -> 0 | AF23: =+SUMIFS(AF:AF,$C:$C,$I23,$D:$D,$J23) -> 0 | AG23: =+SUMIFS(AG:AG,$C:$C,$I23,$D:$D,$J23) -> 0 | AH23: =+SUMIFS(AH:AH,$C:$C,$I23,$D:$D,$J23) -> 0 | AI23: =+SUMIFS(AI:AI,$C:$C,$I23,$D:$D,$J23) -> 0 | AJ23: =+SUMIFS(AJ:AJ,$C:$C,$I23,$D:$D,$J23) -> 0 | AK23: =+SUMIFS(AK:AK,$C:$C,$I23,$D:$D,$J23) -> 0 | AL23: =+SUMIFS(AL:AL,$C:$C,$I23,$D:$D,$J23) -> 0 | AM23: =+SUMIFS(AM:AM,$C:$C,$I23,$D:$D,$J23) -> 0 | AN23: =+SUMIFS(AN:AN,$C:$C,$I23,$D:$D,$J23) -> 0 | AO23: =+SUMIFS(AO:AO,$C:$C,$I23,$D:$D,$J23) -> 0
I24: 부동산 | J24: 임대 | R24: =+SUMIFS(R:R,$C:$C,$I24,$D:$D,$J24) -> 0 | S24: =+SUMIFS(S:S,$C:$C,$I24,$D:$D,$J24) -> 0 | T24: =+SUMIFS(T:T,$C:$C,$I24,$D:$D,$J24) -> 0 | AC24: =+SUMIFS(AC:AC,$C:$C,$I24,$D:$D,$J24) -> 0 | AD24: =+SUMIFS(AD:AD,$C:$C,$I24,$D:$D,$J24) -> 0 | AE24: =+SUMIFS(AE:AE,$C:$C,$I24,$D:$D,$J24) -> 0 | AF24: =+SUMIFS(AF:AF,$C:$C,$I24,$D:$D,$J24) -> 53306844 | AG24: =+SUMIFS(AG:AG,$C:$C,$I24,$D:$D,$J24) -> 53306845 | AH24: =+SUMIFS(AH:AH,$C:$C,$I24,$D:$D,$J24) -> 53306845 | AI24: =+SUMIFS(AI:AI,$C:$C,$I24,$D:$D,$J24) -> 0 | AJ24: =+SUMIFS(AJ:AJ,$C:$C,$I24,$D:$D,$J24) -> 0 | AK24: =+SUMIFS(AK:AK,$C:$C,$I24,$D:$D,$J24) -> 0 | AL24: =+SUMIFS(AL:AL,$C:$C,$I24,$D:$D,$J24) -> 0 | AM24: =+SUMIFS(AM:AM,$C:$C,$I24,$D:$D,$J24) -> 0 | AN24: =+SUMIFS(AN:AN,$C:$C,$I24,$D:$D,$J24) -> 0 | AO24: =+SUMIFS(AO:AO,$C:$C,$I24,$D:$D,$J24) -> 159920533
I25: 아산 | J25: 제조 | L25: =+SUMIFS(L:L,$C:$C,$I25,$D:$D,$J25) -> 0 | M25: =+SUMIFS(M:M,$C:$C,$I25,$D:$D,$J25) -> 0 | N25: =+SUMIFS(N:N,$C:$C,$I25,$D:$D,$J25) -> 0 | O25: =+SUMIFS(O:O,$C:$C,$I25,$D:$D,$J25) -> 0 | P25: =+SUMIFS(P:P,$C:$C,$I25,$D:$D,$J25) -> 0 | Q25: =+SUMIFS(Q:Q,$C:$C,$I25,$D:$D,$J25) -> 0 | R25: =+SUMIFS(R:R,$C:$C,$I25,$D:$D,$J25) -> 0 | S25: =+SUMIFS(S:S,$C:$C,$I25,$D:$D,$J25) -> 0 | T25: =+SUMIFS(T:T,$C:$C,$I25,$D:$D,$J25) -> 0 | U25: =+SUMIFS(U:U,$C:$C,$I25,$D:$D,$J25) -> 0 | V25: =+SUMIFS(V:V,$C:$C,$I25,$D:$D,$J25) -> 0 | W25: =+SUMIFS(W:W,$C:$C,$I25,$D:$D,$J25) -> 0 | AC25: =+SUMIFS(AC:AC,$C:$C,$I25,$D:$D,$J25) -> 0 | AD25: =+SUMIFS(AD:AD,$C:$C,$I25,$D:$D,$J25) -> 0 | AE25: =+SUMIFS(AE:AE,$C:$C,$I25,$D:$D,$J25) -> 0 | AF25: =+SUMIFS(AF:AF,$C:$C,$I25,$D:$D,$J25) -> 0 | AG25: =+SUMIFS(AG:AG,$C:$C,$I25,$D:$D,$J25) -> 0 | AH25: =+SUMIFS(AH:AH,$C:$C,$I25,$D:$D,$J25) -> 0 | AI25: =+SUMIFS(AI:AI,$C:$C,$I25,$D:$D,$J25) -> 0 | AJ25: =+SUMIFS(AJ:AJ,$C:$C,$I25,$D:$D,$J25) -> 0 | AK25: =+SUMIFS(AK:AK,$C:$C,$I25,$D:$D,$J25) -> 0 | AL25: =+SUMIFS(AL:AL,$C:$C,$I25,$D:$D,$J25) -> 0 | AM25: =+SUMIFS(AM:AM,$C:$C,$I25,$D:$D,$J25) -> 0 | AN25: =+SUMIFS(AN:AN,$C:$C,$I25,$D:$D,$J25) -> 0 | AO25: =+SUMIFS(AO:AO,$C:$C,$I25,$D:$D,$J25) -> 0
I26: 의령 | J26: 제조 | L26: =+SUMIFS(L:L,$C:$C,$I26,$D:$D,$J26) -> 0 | M26: =+SUMIFS(M:M,$C:$C,$I26,$D:$D,$J26) -> 0 | N26: =+SUMIFS(N:N,$C:$C,$I26,$D:$D,$J26) -> 0 | O26: =+SUMIFS(O:O,$C:$C,$I26,$D:$D,$J26) -> 0 | P26: =+SUMIFS(P:P,$C:$C,$I26,$D:$D,$J26) -> 0 | Q26: =+SUMIFS(Q:Q,$C:$C,$I26,$D:$D,$J26) -> 0 | R26: =+SUMIFS(R:R,$C:$C,$I26,$D:$D,$J26) -> 0 | S26: =+SUMIFS(S:S,$C:$C,$I26,$D:$D,$J26) -> 0 | T26: =+SUMIFS(T:T,$C:$C,$I26,$D:$D,$J26) -> 0 | U26: =+SUMIFS(U:U,$C:$C,$I26,$D:$D,$J26) -> 0 | V26: =+SUMIFS(V:V,$C:$C,$I26,$D:$D,$J26) -> 0 | W26: =+SUMIFS(W:W,$C:$C,$I26,$D:$D,$J26) -> 0 | AC26: =+SUMIFS(AC:AC,$C:$C,$I26,$D:$D,$J26) -> 0 | AD26: =+SUMIFS(AD:AD,$C:$C,$I26,$D:$D,$J26) -> 0 | AE26: =+SUMIFS(AE:AE,$C:$C,$I26,$D:$D,$J26) -> 0 | AF26: =+SUMIFS(AF:AF,$C:$C,$I26,$D:$D,$J26) -> 0 | AG26: =+SUMIFS(AG:AG,$C:$C,$I26,$D:$D,$J26) -> 0 | AH26: =+SUMIFS(AH:AH,$C:$C,$I26,$D:$D,$J26) -> 0 | AI26: =+SUMIFS(AI:AI,$C:$C,$I26,$D:$D,$J26) -> 0 | AJ26: =+SUMIFS(AJ:AJ,$C:$C,$I26,$D:$D,$J26) -> 0 | AK26: =+SUMIFS(AK:AK,$C:$C,$I26,$D:$D,$J26) -> 0 | AL26: =+SUMIFS(AL:AL,$C:$C,$I26,$D:$D,$J26) -> 0 | AM26: =+SUMIFS(AM:AM,$C:$C,$I26,$D:$D,$J26) -> 0 | AN26: =+SUMIFS(AN:AN,$C:$C,$I26,$D:$D,$J26) -> 0 | AO26: =+SUMIFS(AO:AO,$C:$C,$I26,$D:$D,$J26) -> 0
I27: 의령 | J27: 연구 | L27: =+SUMIFS(L:L,$C:$C,$I27,$D:$D,$J27) -> 0 | M27: =+SUMIFS(M:M,$C:$C,$I27,$D:$D,$J27) -> 0 | N27: =+SUMIFS(N:N,$C:$C,$I27,$D:$D,$J27) -> 0 | O27: =+SUMIFS(O:O,$C:$C,$I27,$D:$D,$J27) -> 0 | P27: =+SUMIFS(P:P,$C:$C,$I27,$D:$D,$J27) -> 0 | Q27: =+SUMIFS(Q:Q,$C:$C,$I27,$D:$D,$J27) -> 0 | R27: =+SUMIFS(R:R,$C:$C,$I27,$D:$D,$J27) -> 0 | S27: =+SUMIFS(S:S,$C:$C,$I27,$D:$D,$J27) -> 0 | T27: =+SUMIFS(T:T,$C:$C,$I27,$D:$D,$J27) -> 0 | U27: =+SUMIFS(U:U,$C:$C,$I27,$D:$D,$J27) -> 0 | V27: =+SUMIFS(V:V,$C:$C,$I27,$D:$D,$J27) -> 0 | W27: =+SUMIFS(W:W,$C:$C,$I27,$D:$D,$J27) -> 0 | AC27: =+SUMIFS(AC:AC,$C:$C,$I27,$D:$D,$J27) -> 0 | AD27: =+SUMIFS(AD:AD,$C:$C,$I27,$D:$D,$J27) -> 0 | AE27: =+SUMIFS(AE:AE,$C:$C,$I27,$D:$D,$J27) -> 0 | AF27: =+SUMIFS(AF:AF,$C:$C,$I27,$D:$D,$J27) -> 0 | AG27: =+SUMIFS(AG:AG,$C:$C,$I27,$D:$D,$J27) -> 0 | AH27: =+SUMIFS(AH:AH,$C:$C,$I27,$D:$D,$J27) -> 0 | AI27: =+SUMIFS(AI:AI,$C:$C,$I27,$D:$D,$J27) -> 0 | AJ27: =+SUMIFS(AJ:AJ,$C:$C,$I27,$D:$D,$J27) -> 0 | AK27: =+SUMIFS(AK:AK,$C:$C,$I27,$D:$D,$J27) -> 0 | AL27: =+SUMIFS(AL:AL,$C:$C,$I27,$D:$D,$J27) -> 0 | AM27: =+SUMIFS(AM:AM,$C:$C,$I27,$D:$D,$J27) -> 0 | AN27: =+SUMIFS(AN:AN,$C:$C,$I27,$D:$D,$J27) -> 0 | AO27: =+SUMIFS(AO:AO,$C:$C,$I27,$D:$D,$J27) -> 0
I28: 제천 | J28: 판관 | L28: =+SUMIFS(L:L,$C:$C,$I28,$D:$D,$J28) -> 0 | M28: =+SUMIFS(M:M,$C:$C,$I28,$D:$D,$J28) -> 0 | N28: =+SUMIFS(N:N,$C:$C,$I28,$D:$D,$J28) -> 0 | O28: =+SUMIFS(O:O,$C:$C,$I28,$D:$D,$J28) -> 0 | P28: =+SUMIFS(P:P,$C:$C,$I28,$D:$D,$J28) -> 0 | Q28: =+SUMIFS(Q:Q,$C:$C,$I28,$D:$D,$J28) -> 0 | R28: =+SUMIFS(R:R,$C:$C,$I28,$D:$D,$J28) -> 0 | S28: =+SUMIFS(S:S,$C:$C,$I28,$D:$D,$J28) -> 0 | T28: =+SUMIFS(T:T,$C:$C,$I28,$D:$D,$J28) -> 0 | U28: =+SUMIFS(U:U,$C:$C,$I28,$D:$D,$J28) -> 0 | V28: =+SUMIFS(V:V,$C:$C,$I28,$D:$D,$J28) -> 0 | W28: =+SUMIFS(W:W,$C:$C,$I28,$D:$D,$J28) -> 0 | AC28: =+SUMIFS(AC:AC,$C:$C,$I28,$D:$D,$J28) -> 0 | AD28: =+SUMIFS(AD:AD,$C:$C,$I28,$D:$D,$J28) -> 0 | AE28: =+SUMIFS(AE:AE,$C:$C,$I28,$D:$D,$J28) -> 0 | AF28: =+SUMIFS(AF:AF,$C:$C,$I28,$D:$D,$J28) -> 0 | AG28: =+SUMIFS(AG:AG,$C:$C,$I28,$D:$D,$J28) -> 0 | AH28: =+SUMIFS(AH:AH,$C:$C,$I28,$D:$D,$J28) -> 0 | AI28: =+SUMIFS(AI:AI,$C:$C,$I28,$D:$D,$J28) -> 0 | AJ28: =+SUMIFS(AJ:AJ,$C:$C,$I28,$D:$D,$J28) -> 0 | AK28: =+SUMIFS(AK:AK,$C:$C,$I28,$D:$D,$J28) -> 0 | AL28: =+SUMIFS(AL:AL,$C:$C,$I28,$D:$D,$J28) -> 0 | AM28: =+SUMIFS(AM:AM,$C:$C,$I28,$D:$D,$J28) -> 0 | AN28: =+SUMIFS(AN:AN,$C:$C,$I28,$D:$D,$J28) -> 0 | AO28: =+SUMIFS(AO:AO,$C:$C,$I28,$D:$D,$J28) -> 0
AO29: =+IF(SUM(AO23:AO28)-AO7=0,"일치","오류") -> 오류

Sheet 4600_투자부동산_적격지출
B1: 적격자산 분석
C4: (1) 2025년 12월 31일 기준 현재 적격자산 현황
C5: 기준일 | D5: 46022
C6: 구분 (본계정) | D6: 46022 | E6: 상당한기간 소요 여부 <주1> | F6: 사용가능 여부 <주2> | G6: 공정가치 측정대상 <주3> | H6: 적격자산
C7: 투자부동산_토지 | D7: 0 | E7: Y | F7: N | G7: N | H7: =IF(E7="Y",IF(F7="N",IF(G7="N","적격자산 해당","n/a"),"n/a"),"n/a") -> 적격자산 해당
C8: 투자부동산_건설중인자산 | D8: =SUM(G214:G393) -> 2036673641 | E8: Y | F8: N | G8: N | H8: =IF(E8="Y",IF(F8="N",IF(G8="N","적격자산 해당","n/a"),"n/a"),"n/a") -> 적격자산 해당
C9: 투자부동산 계 | D9: =SUM(D7:D8) -> 2036673641
C11: <주 1> 상당한기간 소요
C12: K-IFRS 1023호 차입원가
C13: 용어의 정의
C14: 적격자산
C15: - 적격자산: 의도된 용도로 사용(또는 판매) 가능하게 하는 데 상당한 기간을 필요로 하는 자산
C19: <주 2> 사용가능여부
C20: K-IFRS 1023호 차입원가
C21: 문단 24
C22: 적격자산의 건설활동을 여러 부분으로 나누어 완성하고, 남아있는 부분의 건설활동을 계속 진행하고 있더라도 이미 완성된 부분이 사용 가능하다면, 당해 부분을 의도된 용도로 사용(또는 판매) 가능하게 하는 데 필요한 대부분의 활동을 완료한 시점에 차입원가의 자본화를 종료한다.
C24: 문단 24
C25: 남아있는 부분의 건설활동이 계속 진행되고 있더라도 이미 완성된 부분이 사용 가능한 적격자산의 예로는 각각의 건물별로 사용 가능한 여러 동의 건물로 구성된 복합업무시설을 들 수 있다.
C26: 개별부분이 사용되기 위해 자산전체의 건설활동이 완료되어야 하는 적격자산의 예로는 제철소와 같이 동일한 장소에서 여러 생산부문별 공정이 순차적으로 이루어지는 여러 생산공정을 갖춘 산업설비를 들 수 있다.
... C37: 하지만 IASB는 공정가치로 측정되는 자산에 대하여 IAS 23의 요구사항을 적용하지 않는다는 조항이 기업으로 하여금 그러한 자산을 공정가치로 측정하기 전에 차입원가를 자본화시켰을 경우 그 효과를 반영하여 손익항목을 표시하는 것까지 금지하지는 않는다는 데 주목하였다.
C41: 건설중인자산_투자부동산 | G41: =SUM(G43:G393) -> 16473502551 | H41: =SUM(H43:H393) -> 7072519926
C42: 계정과목명 | D42: 회계일자 | E42: 적요 | F42: 관리항목1 | G42: 차변 | H42: 대변 | I42: 잔액
C43: 투자부동산_건설중인자산 | D43: 44926 | E43: 전기이월 | I43: 0
C44: 투자부동산_건설중인자산 | D44: 2023-05-23 | E44: 토지(부대비용) / 투자부동산(신당동)용도 변경에 따른 건축사 용역수수료 / 202305-경영기획팀-21 | F44: [거래처코드]R06972 : (주)제이플러스건축사사무소 (492-87-00025) | G44: 3500000 | H44: 0 | I44: 3500000
C45: 투자부동산_건설중인자산 | D45: 2023-05-23 | E45: 토지(부대비용) / 투자부동산(신당동)용도 변경에 따른 건축사 용역수수료 / 202305-경영기획팀-21 | F45: [거래처코드]R06972 : (주)제이플러스건축사사무소 (492-87-00025) | G45: 350000 | H45: 0 | I45: 3850000
C46: 투자부동산_건설중인자산 | D46: 2023-05-23 | E46: 토지(철거비용) 투자부동산(신당동)용도 변경에 따른 철거비용 / 202305-경영기획팀-21 | F46: [거래처코드]R06973 : 국대 (501-15-37697) | G46: 700000 | H46: 0 | I46: 4550000
C47: 투자부동산_건설중인자산 | D47: 2023-05-23 | E47: 토지(철거비용) 투자부동산(신당동)용도 변경에 따른 철거비용 / 202305-경영기획팀-21 | F47: [거래처코드]R06973 : 국대 (501-15-37697) | G47: 70000 | H47: 0 | I47: 4620000
C48: 투자부동산_건설중인자산 | D48: 2023-05-26 | E48: 경영기획팀 / 05.26. / 투자부동산(신당동)신축건물 설계용역 관련 계약(계약금) / 202305-경영기획팀-24 | F48: [거래처코드]R06966 : 오이이아이 건축디자인스튜디오 (795-39-00898) | G48: 64686300 | H48: 0 | I48: 69306300
C49: 투자부동산_건설중인자산 | D49: 2023-06-13 | E49: 토지(토지매입) 투자부동산(신당동160-14,신당동16-15 외)/202302-경영기획팀-19 | F49: [거래처코드]P00027 : 우리은행 신사동점 (201-81-02819) | G49: 2800000000 | H49: 0 | I49: 2869306300
C50: 투자부동산_건설중인자산 | D50: 2023-06-13 | E50: 토지(토지매입) 투자부동산(신당동160-14,신당동16-15 외)/202302-경영기획팀-19 | F50: [거래처코드]P00027 : 우리은행 신사동점 (201-81-02819) | G50: 2400000000 | H50: 0 | I50: 5269306300
C51: 투자부동산_건설중인자산 | D51: 2023-06-13 | E51: 토지(토지매입) 투자부동산(신당동160-14,160-15 외)/202302-경영기획팀-19 | F51: [거래처코드]P00027 : 우리은행 신사동점 (201-81-02819) | G51: 1174000000 | H51: 0 | I51: 6443306300
C52: 투자부동산_건설중인자산 | D52: 2023-06-13 | E52: 토지(부대비용) / 투자부동산 매매계약에 따른 인지세 납부 / 202302-경영기획팀-20 | F52: [거래처코드]P00027 : 우리은행 신사동점 (201-81-02819) | G52: 350000 | H52: 0 | I52: 6443656300
C53: 투자부동산_건설중인자산 | D53: 2023-06-13 | E53: 토지(건물매입) / 투자부동산 (신당동160-14,160-15외)/ 202302-경영기획팀-20 | F53: [거래처코드]P00027 : 우리은행 신사동점 (201-81-02819) | G53: 126000000 | H53: 0 | I53: 6569656300
C54: 투자부동산_건설중인자산 | D54: 2023-06-13 | E54: 토지(건물매입) / 투자부동산 매매계약에 따른 건물분(상가)부가세 불공 건 건설중인 자산 계정 처리 / 202302-경영기획팀-19 | F54: [거래처코드]R06930 : 김영환 (346-11-00881) | G54: 960000 | H54: 0 | I54: 6570616300
C55: 투자부동산_건설중인자산 | D55: 2023-06-13 | E55: 토지(부대비용) / 투자부동산 계약완료에 따른 부동산 중개수수료 지급(신당동 160-14) / 202306-경영기획팀-18 | F55: [거래처코드]R06917 : (주)알파카부동산중개법인 (379-88-01636) | G55: 28000000 | H55: 0 | I55: 6598616300
... C58: 투자부동산_건설중인자산 | D58: 2023-06-13 | E58: 토지(부대비용) / 투자부동산 계약완료에 따른 부동산 중개수수료 지급(신당동 160-15 외) / 202306-경영기획팀-18 | F58: [거래처코드]R06917 : (주)알파카부동산중개법인 (379-88-01636) | G58: 2400000 | H58: 0 | I58: 6627816300
C59: 투자부동산_건설중인자산 | D59: 2023-06-14 | E59: 토지(부대비용) / 투자부동산(신당동)용도 변경에 따른 건축사 용역수수료 / 202305-경영기획팀-21 | G59: 0 | H59: 3850000 | I59: 6623966300
C60: 투자부동산_건설중인자산 | D60: 2023-06-14 | E60: 토지(철거비용) 투자부동산(신당동)용도 변경에 따른 철거비용 / 202305-경영기획팀-21 | G60: 0 | H60: 770000 | I60: 6623196300
C61: 투자부동산_건설중인자산 | D61: 2023-06-14 | E61: 토지(토지매입) 투자부동산(신당동160-14,신당동16-15 외)/202302-경영기획팀-19 | G61: 0 | H61: 2800000000 | I61: 3823196300
C62: 투자부동산_건설중인자산 | D62: 2023-06-14 | E62: 토지(토지매입) 투자부동산(신당동160-14,신당동16-15 외)/202302-경영기획팀-19 | G62: 0 | H62: 2400000000 | I62: 1423196300
...

Sheet 4600_투자부동산_대상이자비용
B4: 자본화대상 차입원가 분석
C9: (1) 26년 1분기말 기준 현재 차입금 등 현황
C10: 기준일 | D10: 46112
C11: 차입명 | D11: 금융기관 명 | E11: 구분 | F11: 변경 전 금액 | G11: 변경 후 금액 | H11: 내역 | I11: 최초차입일 | J11: 당초 만기일 | K11: 변경 전 이자율 | L11: 변경 만기일 | M11: 변경 후 이자율 | N11: 차입금 분류 | O11: 상환여부
C12: 차입금 | D12: 신한은행 | E12: 일반자금 | F12: 5000000000 | G12: 5000000000 | H12: 운전자금 | I12: 46023 | J12: 46112 | K12: 0.045 | L12: 46112 | M12: 0.045 | N12: 단기차입금 | O12: Rollover 차입금
C13: 차입금 | D13: 신한은행 | E13: 일반자금 | F13: 24000000000 | G13: 24000000000 | H13: 운전자금 | I13: 46023 | J13: 46035 | K13: 0.0369 | L13: 46035 | M13: 0.0384 | N13: 유동성장기차입금 | O13: 부
C14: 차입금 | D14: 신한은행 | E14: 일반자금 | F14: 24000000000 | G14: 24000000000 | H14: 운전자금 | I14: 46036 | J14: 46112 | K14: 0.0384 | L14: 46112 | M14: 0.0384 | N14: 유동성장기차입금 | O14: 부
C15: 차입금 | D15: 신한은행 | E15: 시설자금 | F15: 4000000000 | G15: 4000000000 | H15: 시설자금 | I15: 46023 | J15: 46112 | K15: 0.0366 | L15: 46112 | M15: 0.0366 | N15: 장기차입금 | O15: 부
C16: 전환사채 | D16: 기타 | E16: 전환사채 관련 이자 | F16: 0 | G16: 0 | H16: - | N16: 전환사채 | O16: 부
C17: 리스부채 | D17: 기타 | E17: 리스부채 관련 이자 | F17: 0 | G17: 0 | H17: - | N17: 리스부채 | O17: 리스상각
C21: <주 1> 차입원가 해당여부
C22: K-IFRS 1023호 차입원가
C23: 용어의 정의_문단 5
C24: 차입원가
C25: - 차입원가: 자금의 차입과 관련하여 발생하는 이자 및 기타 원가
C27: 용어의 정의_문단 6
C28: 차입원가는 다음과 같은 항목을 포함할 수 있다.
C29: (1) 기업회계기준서 제1109호에서 기술한 유효이자율법을 사용하여 계산된 이자비용
C30: (2) 기업회계기준서 제1116호 ‘리스’에 따라 인식하는 리스부채 관련 이자
C31: (3) 외화차입금과 관련되는 외환차이 중 이자원가의 조정으로 볼 수 있는 부분
C36: <주 2> 특정목적 차입여부
C37: K-IFRS 1023호 차입원가
... C79: 문단 14를 개정하여 ‘모든’ 차입금을 명시함에 따라 이 점을 명확히 하였다.
B1048533: O
B1048534: X
B1048535: 토지
B1048536: 건물
B1048537: 구축물
B1048538: 기계장치
B1048539: 차량운반구
B1048540: 기타(토지 포함)

Sheet 4600_투자부동산_차입원가자본화
B1: 차입원가 자본화 Schedule
B3: 시작일 | C3: 46023 | D3: =C4-C3+1 -> 90
B4: 기준일 | C4: 46112 | Q4: 31일기준
B5: 차입명 | C5: 금융기관 명 | D5: 구분 | E5: 변경 전 금액 | F5: 변경 후 금액 | G5: 내역 | H5: 최초차입일 | I5: 당초 만기일 | J5: 변경 전 이자율 | K5: 변경 만기일 | L5: 변경 후 이자율 | M5: 차입금 분류 | N5: 상환여부 | O5: 이자비용 | P5: 차입일수 | Q5: 연평균차입금 | R5: 가중평균 차입이자율
A6: 2 | B6: 차입금 | C6: 신한은행 | D6: 일반자금 | E6: 5000000000 | F6: 5000000000 | G6: 운전자금 | H6: 46023 | I6: 46112 | J6: 0.045 | K6: 46112 | L6: 0.045 | M6: 단기차입금 | N6: Rollover 차입금 | O6: 55479450 | P6: =MIN(I6-$C$3,366,$C$4-H6,I6-H6)+1 -> 90 | Q6: =F6*P6/90 -> 5000000000 | R6: =O6/Q6 -> 0.01109589 | S6: a
A7: 3 | B7: 차입금 | C7: 신한은행 | D7: 일반자금 | E7: 24000000000 | F7: 24000000000 | G7: 운전자금 | H7: 46023 | I7: 46035 | J7: 0.0369 | K7: 46035 | L7: 0.0384 | M7: 유동성장기차입금 | N7: 부 | O7: 29115616 | P7: =MIN(I7-$C$3,366,$C$4-H7,I7-H7)+1 -> 13 | Q7: =F7*P7/90 -> 3.4666667e+09 | R7: =O7/Q7 -> 0.0083987354 | S7: b
B8: 차입금 | C8: 신한은행 | D8: 일반자금 | E8: 24000000000 | F8: 24000000000 | G8: 운전자금 | H8: 46036 | I8: 46112 | J8: 0.0384 | K8: 46112 | L8: 0.0384 | M8: 유동성장기차입금 | N8: 부 | O8: 166645478 | P8: =MIN(I8-$C$3,366,$C$4-H8,I8-H8)+1 -> 77 | Q8: =F8*P8/90 -> 2.0533333e+10 | R8: =O8/Q8 -> 0.0081158512 | S8: C
A9: 4 | B9: 차입금 | C9: 신한은행 | D9: 시설자금 | E9: 4000000000 | F9: 4000000000 | G9: 시설자금 | H9: 46023 | I9: 46112 | J9: 0.0366 | K9: 46112 | L9: 0.0366 | M9: 장기차입금 | N9: 부 | O9: 36098627 | P9: =MIN(I9-$C$3,366,$C$4-H9,I9-H9)+1 -> 90 | Q9: =F9*P9/90 -> 4000000000 | R9: =O9/Q9 -> 0.0090246568 | S9: d
A10: 21 | B10: 전환사채 | C10: 기타 | D10: 전환사채 관련 이자 | E10: 0 | F10: 0 | G10: - | M10: 전환사채 | N10: 부 | O10: 136828005 | Q10: =L22 -> 2.3061821e+09 | R10: =O10/Q10 -> 0.059330962 | S10: e | T10: <주1>
B11: 리스부채 | C11: 기타 | D11: 리스부채 관련 이자 | E11: 0 | F11: 0 | G11: - | M11: 리스부채 | N11: 리스상각 | O11: 8632420 | Q11: =J31 -> 5.91884e+08 | R11: =O11/Q11 -> 0.014584648 | S11: f | T11: <주2>
O12: =SUM(O6:O11)-O9 -> 396700969 | Q12: =SUM(Q6:Q11)-Q9 -> 3.1898066e+10 | R12: =O12/Q12 -> 0.012436521
B13: <주1> | O13: =O12-C48 -> 0
B14: 전환사채 | C14: 일자 | D14: 기초 | E14: 전환 | F14: 발행 | G14: 평가 | H14: 상각 | I14: 잔액 | J14: 일수 | K14: 적수 | L14: 연평균
C15: 46023 | D15: 2270470844 | I15: =D15+E15+F15+G15+H15 -> 2270470844 | J15: =C16-C15 -> 9 | K15: =I15*J15 -> 20434237596 | L15: =K15/90 -> 2.2704708e+08
C16: 46032 | D16: =I15 -> 2270470844 | H16: -15197893 | I16: =D16+E16+F16+G16-H16 -> 2285668737 | J16: =C17-C16 -> 21 | K16: =I16*J16 -> 47999043477 | L16: =K16/90 -> 5.3332271e+08
C17: 46053 | D17: =I16 -> 2285668737 | H17: -9510738 | I17: =D17+E17+F17+G17-H17 -> 2295179475 | J17: =C18-C17 -> 10 | K17: =I17*J17 -> 22951794750 | L17: =K17/90 -> 2.5501994e+08
C18: 46063 | D18: =I17 -> 2295179475 | H18: -15415155 | I18: =D18+E18+F18+G18-H18 -> 2310594630 | J18: =C19-C18 -> 18 | K18: =I18*J18 -> 41590703340 | L18: =K18/90 -> 462118926
C19: 46081 | D19: =I18 -> 2310594630 | H19: -7859049 | I19: =D19+E19+F19+G19-H19 -> 2318453679 | J19: =C20-C19 -> 10 | K19: =I19*J19 -> 23184536790 | L19: =K19/90 -> 2.5760596e+08
C20: 46091 | D20: =I19 -> 2318453679 | H20: -17276136 | I20: =D20+E20+F20+G20-H20 -> 2335729815 | J20: =C21-C20 -> 21 | K20: =I20*J20 -> 49050326115 | L20: =K20/90 -> 5.4500362e+08
C21: 46112 | D21: =I20 -> 2335729815 | H21: -10019860 | I21: =D21+E21+F21+G21-H21 -> 2345749675 | J21: =C22-C21 -> 1 | K21: =I21*J21 -> 2345749675 | L21: =K21/90 -> 26063885
C22: 46113 | E22: =SUM(E15:E19) -> 0 | H22: =SUM(H16:H21) -> -75278831 | J22: =SUM(J15:J21) -> 90 | K22: =SUM(K15:K21) -> 207556391743 | L22: =K22/90 -> 2.3061821e+09
B25: <주2>
B26: 리스부채 | C26: 일자 | D26: 기초 | E26: 신규 | F26: 상환 | G26: 잔액 | H26: 일수 | I26: 적수 | J26: 연평균
C27: 46023 | D27: 611325726 | G27: =D27-E27+F27 -> 611325726 | H27: =C28-C27 -> 30 | I27: =G27*H27 -> 18339771780 | J27: =I27/90 -> 203775242
C28: 46053 | D28: =G27 -> 611325726 | F28: 21103827 | G28: =D28+E28-F28 -> 590221899 | H28: =C29-C28 -> 28 | I28: =G28*H28 -> 16526213172 | J28: =I28/90 -> 1.8362459e+08
C29: 46081 | D29: =G28 -> 590221899 | E29: 7019197 | F29: 21464500 | G29: =D29+E29-F29 -> 575776596 | H29: =C30-C29 -> 31 | I29: =G29*H29 -> 17849074476 | J29: =I29/90 -> 1.9832305e+08
C30: 46112 | D30: =G29 -> 575776596 | F30: 21276253 | G30: =D30+E30-F30 -> 554500343 | H30: =C31-C30 -> 1 | I30: =G30*H30 -> 554500343 | J30: =I30/90 -> 6161114.9
C31: 46113 | E31: =SUM(E27:E30) -> 7019197 | F31: =SUM(F27:F30) -> 63844580 | H31: =SUM(H27:H30) -> 90 | I31: =SUM(I27:I30) -> 53269559771 | J31: =SUM(J27:J30) -> 5.91884e+08
B36: 1) 특정차입금
B37: 신한은행 시설자금(투자부동산)
B38: 이자비용 | C38: =O9 -> 36098627
B39: 특정차입금 | C39: =F9 -> 4000000000
B41: 2) 일반차입금
B42: 투자부동산_토지 | D42: 투자부동산_건설중인자산
B43: 특정차입금 | C43: =C39 -> 4000000000 | D43: 특정차입금
B44: 일반차입금 | D44: 일반차입금
B45: 연평균지출액 | C45: ='4600_투자부동산_적격지출'!K821 -> 7072519926 | D45: 연평균지출액 | E45: ='4600_투자부동산_적격지출'!K814 -> 9.030117e+09
B46: 자본화대상이자비용 | C46: =MIN(C45-C43)*$R$12 -> 38211459 | D46: 자본화대상이자비용 | E46: =(E45-E43)*R12 -> 1.1230324e+08
B48: 실제지출총액(한도) | C48: =O12 -> 396700969
B49: 자본화대상 | C49: =(C46+E46+C38) -> 1.8661333e+08
...

Sheet 4600_투자부동산_주석
A3: (1) 당반기와 전반기 중 투자부동산의 변동내역은 다음과 같습니다.
A5: (단위: 원)
A6: 구분 | B6: 당반기 | C6: 전반기
A7: 기초 | B7: 35949802624 | C7: 39217355654
A8: 취득 | B8: 644565228 | C8: 1297691450 | D8: =B8='4600_투자부동산'!B34 -> TRUE
A9: 처분 | B9: 0
A10: 감가상각비 | B10: -148761889 | C10: -88097949 | D10: =B10=-'4700_유형자산_분석적검토'!B23 -> TRUE
A11: 손상 | B11: 0
A12: 기타(*1) | B12: -9848600697
A13: 반기말(*2) | B13: 26597005266 | C13: 40426949155
B15: =B13='4600_투자부동산'!E18+'4600_투자부동산'!E22 -> TRUE
B17: 계정명 | C17: 대체증가 | D17: 대체감소 | E17: 순증감
B18: 토지 | C18: ='4600_투자부동산'!D38 -> 4280784678 | D18: ='4600_투자부동산'!J38 -> 7072519926 | E18: =C18-D18 -> -2791735248
B19: 건물 | C19: ='4600_투자부동산'!D39 -> 12292305202 | D19: ='4600_투자부동산'!J39 -> 11147763220 | E19: =C19-D19 -> 1144541982
B20: 감누액 | C20: ='4600_투자부동산'!C41 -> -225729098 | D20: =-'4600_투자부동산_매각예정자산대체'!C37 -> -67022507 | E20: =C20-D20 -> -158706591
B21: 손상차손 | E21: =C21-D21 -> 0
B22: 건설중인자산 | C22: ='4600_투자부동산'!D40 -> 0 | D22: ='4600_투자부동산'!J40 -> 11147763220 | E22: =C22-D22 -> -11147763220
B23: 손상차손 | D23: ='4600_투자부동산'!J42 -> -3105062380 | E23: =C23-D23 -> 3105062380
B24: 합계 | C24: =SUM(C18:C23) -> 16347360782 | D24: =SUM(D18:D23) -> 26195961479 | E24: =SUM(E18:E23) -> -9848600697 | F24: =E24-B12 -> 0 | G24: 신당동 감가비
A27: (2) 당반기 및 전반기 중 투자부동산과 관련하여 손익으로 인식한 내역은 다음과 같습니다.
A28: 구분 | B28: 당반기 | C28: 전반기
A29: 임대매출 | B29: =SUMIF(데이터개요_계정별!$A$2:$A$600,'4600_투자부동산_주석'!A29,데이터개요_계정별!$G$2:$G$400) -> 213843315 | C29: 185031787
A30: 임대매출원가 | B30: =SUMIF(데이터개요_계정별!$A$2:$A$600,'4600_투자부동산_주석'!A30,데이터개요_계정별!$C$2:$C$400) -> 161802713 | C30: 171147667

Sheet 4700_유형자산
A2: =기본사항!C8 -> 주식회사 경남제약 | G2: 조서No. 4701
A3: 유형자산
A4: LEAD SCHEDULE
A5: 작성자 | C5: =기본사항!C11 -> 이병하 | E5: 검토자 | G5: =기본사항!C13 -> 이광우
A6: 작성일 | C6: =기본사항!C12 -> 46227 | E6: 검토일 | G6: =기본사항!C14 -> 46227
A7: 결산일 | C7: =기본사항!C10 -> 46203
A10: 취득원가 | E10: =기본사항!C10 -> 46203 | I10: 비 고
A11: ACCOUNT | B11: 전기잔액 | C11: INCREASE | D11: DECREASE | E11: PER BOOK | F11: AJE | G11: RES | H11: FINAL | I11: Refer | J11: NOTE
A12: 토지 | B12: 22189289848 | C12: =IFERROR(_xlfn.XLOOKUP(A12,데이터개요_계정별!$A$2:$A$400,데이터개요_계정별!$C$2:$C$400,,0,),0) -> 0 | D12: =IFERROR(_xlfn.XLOOKUP(A12,데이터개요_계정별!$A$2:$A$400,데이터개요_계정별!$G$2:$G$400,,0,),0) -> 4280784678 | E12: =B12+C12-D12 -> 17908505170 | H12: =E12+F12+G12 -> 17908505170 | I12: C710
A13: 건물 | B13: 11609712365 | C13: =IFERROR(_xlfn.XLOOKUP(A13,데이터개요_계정별!$A$2:$A$400,데이터개요_계정별!$C$2:$C$400,,0,),0) -> 0 | D13: =IFERROR(_xlfn.XLOOKUP(A13,데이터개요_계정별!$A$2:$A$400,데이터개요_계정별!$G$2:$G$400,,0,),0) -> 1144541982 | E13: =B13+C13-D13 -> 10465170383 | H13: =E13+F13+G13 -> 10465170383 | I13: C720
A14: 구축물 | B14: 613530000 | C14: =IFERROR(_xlfn.XLOOKUP(A14,데이터개요_계정별!$A$2:$A$400,데이터개요_계정별!$C$2:$C$400,,0,),0) -> 0 | D14: =IFERROR(_xlfn.XLOOKUP(A14,데이터개요_계정별!$A$2:$A$400,데이터개요_계정별!$G$2:$G$400,,0,),0) -> 0 | E14: =B14+C14-D14 -> 613530000 | H14: =E14+F14+G14 -> 613530000 | I14: C721
A15: 기계장치 | B15: 9099800904 | C15: =IFERROR(_xlfn.XLOOKUP(A15,데이터개요_계정별!$A$2:$A$400,데이터개요_계정별!$C$2:$C$400,,0,),0) -> 14000000 | D15: =IFERROR(_xlfn.XLOOKUP(A15,데이터개요_계정별!$A$2:$A$400,데이터개요_계정별!$G$2:$G$400,,0,),0) -> 0 | E15: =B15+C15-D15 -> 9113800904 | H15: =E15+F15+G15 -> 9113800904 | I15: C730
A16: 차량운반구 | B16: 137351362 | C16: =IFERROR(_xlfn.XLOOKUP(A16,데이터개요_계정별!$A$2:$A$400,데이터개요_계정별!$C$2:$C$400,,0,),0) -> 72676310 | D16: =IFERROR(_xlfn.XLOOKUP(A16,데이터개요_계정별!$A$2:$A$400,데이터개요_계정별!$G$2:$G$400,,0,),0) -> 39674148 | E16: =B16+C16-D16 -> 170353524 | H16: =E16+F16+G16 -> 170353524 | I16: C740
A17: 비품 | B17: 1387225020 | C17: =IFERROR(_xlfn.XLOOKUP(A17,데이터개요_계정별!$A$2:$A$400,데이터개요_계정별!$C$2:$C$400,,0,),0) -> 0 | D17: =IFERROR(_xlfn.XLOOKUP(A17,데이터개요_계정별!$A$2:$A$400,데이터개요_계정별!$G$2:$G$400,,0,),0) -> 0 | E17: =B17+C17-D17 -> 1387225020 | H17: =E17+F17+G17 -> 1387225020 | I17: C741
